Workbook

Sheet ① Start Here
B2: ref13 scoring template
B4: What this workbook does: you paste your model's answer for paper ref13, and it tells you how close it is to the benchmark (the correct answer).
B6: HOW TO USE IT — do this 5 times (once per run):
B8: 1. Go to the 'Run 1' tab.
B9: 2. Look at the grey BENCHMARK block on the left: 6 rows, the correct answer.
B10: 3. In your model's answer, find the row that matches each benchmark row's
B11: conditions (species, complex, method, Mg). Paste its 7 values into the blue
B12: 'YOUR MODEL' columns on the same line.
B13: 4. The green AUTO-CHECK columns turn each field into 1 (match) or 0 (no match),
B14: and the SCORE column adds them up out of 7.
B15: 5. The auto-check is rough. If it marked a field 0 but you think the values really
B16: mean the same thing (e.g. '4' vs '4 °C', or 'None' vs '0.001 mM'), type the
... B29: • You never edit the grey or green cells. You only ever type in blue and yellow cells.

Sheet Run 1
A1: RUN 1 | C1: Paste your model's values into the BLUE columns, one benchmark row at a time. The GREEN columns check them automatically.
B2: BENCHMARK — do not edit | J2: YOUR MODEL — paste values here | R2: AUTO-CHECK (rough — you have the final say) | Y2: SCORE
A3: Row | B3: Species | C3: Temp (°C) | D3: Troponin complex | E3: Bound Ca2+ measure | F3: Mg (mM) | G3: Kd (M^-1) | H3: K (µM) | J3: Species | K3: Temp (°C) | L3: Troponin complex | M3: Bound Ca2+ measure | N3: Mg (mM) | O3: Kd (M^-1) | P3: K (µM) | R3: Species | S3: Temp (°C) | T3: Troponin complex | U3: Bound Ca2+ measure | V3: Mg (mM) | W3: Kd (M^-1) | X3: K (µM) | Y3: Auto /7 | Z3: Your /7 (edit only if you disagree) | AA3: Final /7 | AC3: norm(GT):Species | AD3: norm(GT):Temp (°C) | AE3: norm(GT):Troponin complex | AF3: norm(GT):Bound Ca2+ measure | AG3: norm(GT):Mg (mM) | AH3: norm(GT):Kd (M^-1) | AI3: norm(GT):K (µM) | AK3: norm(you):Species | AL3: norm(you):Temp (°C) | AM3: norm(you):Troponin complex | AN3: norm(you):Bound Ca2+ measure | AO3: norm(you):Mg (mM) | AP3: norm(you):Kd (M^-1) | AQ3: norm(you):K (µM)
A4: 1 | B4: Bovine | C4: 4 | D4: TnC | E4: SC | F4: None | G4: 2.5 x 10^5 | H4: 4 | R4: =IF(J4="",0,IF(EXACT($AC4,$AK4),1,IF(IFERROR(VALUE($AC4)=VALUE($AK4),FALSE),1,0))) | S4: =IF(K4="",0,IF(EXACT($AD4,$AL4),1,IF(IFERROR(VALUE($AD4)=VALUE($AL4),FALSE),1,0))) | T4: =IF(L4="",0,IF(EXACT($AE4,$AM4),1,IF(IFERROR(VALUE($AE4)=VALUE($AM4),FALSE),1,0))) | U4: =IF(M4="",0,IF(EXACT($AF4,$AN4),1,IF(IFERROR(VALUE($AF4)=VALUE($AN4),FALSE),1,0))) | V4: =IF(N4="",0,IF(EXACT($AG4,$AO4),1,IF(IFERROR(VALUE($AG4)=VALUE($AO4),FALSE),1,0))) | W4: =IF(O4="",0,IF(EXACT($AH4,$AP4),1,IF(IFERROR(VALUE($AH4)=VALUE($AP4),FALSE),1,0))) | X4: =IF(P4="",0,IF(EXACT($AI4,$AQ4),1,IF(IFERROR(VALUE($AI4)=VALUE($AQ4),FALSE),1,0))) | Y4: =SUM(R4:X4) | AA4: =IF(Z4="",Y4,Z4) | AC4: =TRIM(SUBSTITUTE(SUBSTITUTE(SUBSTITUTE(SUBSTITUTE(SUBSTITUTE(SUBSTITUTE(SUBSTITUTE(SUBSTITUTE(SUBSTITUTE(SUBSTITUTE(SUBSTITUTE(SUBSTITUTE(SUBSTITUTE(LOWER(SUBSTITUTE(SUBSTITUTE(SUBSTITUTE(SUBSTITUTE(SUBSTITUTE(B4,"×","x"),"·",""),"−","-"),"–","-"),"^","")),"μ","u"),"µ","u")," ",""),"k1=",""),"k2=",""),"k3=",""),"kd=",""),"ka=",""),"k=",""),"°c",""),"m-1",""),"um",""),"mm","")) | AD4: =TRIM(SUBSTITUTE(SUBSTITUTE(SUBSTITUTE(SUBSTITUTE(SUBSTITUTE(SUBSTITUTE(SUBSTITUTE(SUBSTITUTE(SUBSTITUTE(SUBSTITUTE(SUBSTITUTE(SUBSTITUTE(SUBSTITUTE(LOWER(SUBSTITUTE(SUBSTITUTE(SUBSTITUTE(SUBSTITUTE(SUBSTITUTE(C4,"×","x"),"·",""),"−","-"),"–","-"),"^","")),"μ","u"),"µ","u")," ",""),"k1=",""),"k2=",""),"k3=",""),"kd=",""),"ka=",""),"k=",""),"°c",""),"m-1",""),"um",""),"mm","")) | AE4: =TRIM(SUBSTITUTE(SUBSTITUTE(SUBSTITUTE(SUBSTITUTE(SUBSTITUTE(SUBSTITUTE(SUBSTITUTE(SUBSTITUTE(SUBSTITUTE(SUBSTITUTE(SUBSTITUTE(SUBSTITUTE(SUBSTITUTE(LOWER(SUBSTITUTE(SUBSTITUTE(SUBSTITUTE(SUBSTITUTE(SUBSTITUTE(D4,"×","x"),"·",""),"−","-"),"–","-"),"^","")),"μ","u"),"µ","u")," ",""),"k1=",""),"k2=",""),"k3=",""),"kd=",""),"ka=",""),"k=",""),"°c",""),"m-1",""),"um",""),"mm","")) | AF4: =TRIM(SUBSTITUTE(SUBSTITUTE(SUBSTITUTE(SUBSTITUTE(SUBSTITUTE(SUBSTITUTE(SUBSTITUTE(SUBSTITUTE(SUBSTITUTE(SUBSTITUTE(SUBSTITUTE(SUBSTITUTE(SUBSTITUTE(LOWER(SUBSTITUTE(SUBSTITUTE(SUBSTITUTE(SUBSTITUTE(SUBSTITUTE(E4,"×","x"),"·",""),"−","-"),"–","-"),"^","")),"μ","u"),"µ","u")," ",""),"k1=",""),"k2=",""),"k3=",""),"kd=",""),"ka=",""),"k=",""),"°c",""),"m-1",""),"um",""),"mm","")) | AG4: =TRIM(SUBSTITUTE(SUBSTITUTE(SUBSTITUTE(SUBSTITUTE(SUBSTITUTE(SUBSTITUTE(SUBSTITUTE(SUBSTITUTE(SUBSTITUTE(SUBSTITUTE(SUBSTITUTE(SUBSTITUTE(SUBSTITUTE(LOWER(SUBSTITUTE(SUBSTITUTE(SUBSTITUTE(SUBSTITUTE(SUBSTITUTE(F4,"×","x"),"·",""),"−","-"),"–","-"),"^","")),"μ","u"),"µ","u")," ",""),"k1=",""),"k2=",""),"k3=",""),"kd=",""),"ka=",""),"k=",""),"°c",""),"m-1",""),"um",""),"mm","")) | AH4: =TRIM(SUBSTITUTE(SUBSTITUTE(SUBSTITUTE(SUBSTITUTE(SUBSTITUTE(SUBSTITUTE(SUBSTITUTE(SUBSTITUTE(SUBSTITUTE(SUBSTITUTE(SUBSTITUTE(SUBSTITUTE(SUBSTITUTE(LOWER(SUBSTITUTE(SUBSTITUTE(SUBSTITUTE(SUBSTITUTE(SUBSTITUTE(G4,"×","x"),"·",""),"−","-"),"–","-"),"^","")),"μ","u"),"µ","u")," ",""),"k1=",""),"k2=",""),"k3=",""),"kd=",""),"ka=",""),"k=",""),"°c",""),"m-1",""),"um",""),"mm","")) | AI4: =TRIM(SUBSTITUTE(SUBSTITUTE(SUBSTITUTE(SUBSTITUTE(SUBSTITUTE(SUBSTITUTE(SUBSTITUTE(SUBSTITUTE(SUBSTITUTE(SUBSTITUTE(SUBSTITUTE(SUBSTITUTE(SUBSTITUTE(LOWER(SUBSTITUTE(SUBSTITUTE(SUBSTITUTE(SUBSTITUTE(SUBSTITUTE(H4,"×","x"),"·",""),"−","-"),"–","-"),"^","")),"μ","u"),"µ","u")," ",""),"k1=",""),"k2=",""),"k3=",""),"kd=",""),"ka=",""),"k=",""),"°c",""),"m-1",""),"um",""),"mm","")) | AK4: =TRIM(SUBSTITUTE(SUBSTITUTE(SUBSTITUTE(SUBSTITUTE(SUBSTITUTE(SUBSTITUTE(SUBSTITUTE(SUBSTITUTE(SUBSTITUTE(SUBSTITUTE(SUBSTITUTE(SUBSTITUTE(SUBSTITUTE(LOWER(SUBSTITUTE(SUBSTITUTE(SUBSTITUTE(SUBSTITUTE(SUBSTITUTE(J4,"×","x"),"·",""),"−","-"),"–","-"),"^","")),"μ","u"),"µ","u")," ",""),"k1=",""),"k2=",""),"k3=",""),"kd=",""),"ka=",""),"k=",""),"°c",""),"m-1",""),"um",""),"mm","")) | AL4: =TRIM(SUBSTITUTE(SUBSTITUTE(SUBSTITUTE(SUBSTITUTE(SUBSTITUTE(SUBSTITUTE(SUBSTITUTE(SUBSTITUTE(SUBSTITUTE(SUBSTITUTE(SUBSTITUTE(SUBSTITUTE(SUBSTITUTE(LOWER(SUBSTITUTE(SUBSTITUTE(SUBSTITUTE(SUBSTITUTE(SUBSTITUTE(K4,"×","x"),"·",""),"−","-"),"–","-"),"^","")),"μ","u"),"µ","u")," ",""),"k1=",""),"k2=",""),"k3=",""),"kd=",""),"ka=",""),"k=",""),"°c",""),"m-1",""),"um",""),"mm","")) | AM4: =TRIM(SUBSTITUTE(SUBSTITUTE(SUBSTITUTE(SUBSTITUTE(SUBSTITUTE(SUBSTITUTE(SUBSTITUTE(SUBSTITUTE(SUBSTITUTE(SUBSTITUTE(SUBSTITUTE(SUBSTITUTE(SUBSTITUTE(LOWER(SUBSTITUTE(SUBSTITUTE(SUBSTITUTE(SUBSTITUTE(SUBSTITUTE(L4,"×","x"),"·",""),"−","-"),"–","-"),"^","")),"μ","u"),"µ","u")," ",""),"k1=",""),"k2=",""),"k3=",""),"kd=",""),"ka=",""),"k=",""),"°c",""),"m-1",""),"um",""),"mm","")) | AN4: =TRIM(SUBSTITUTE(SUBSTITUTE(SUBSTITUTE(SUBSTITUTE(SUBSTITUTE(SUBSTITUTE(SUBSTITUTE(SUBSTITUTE(SUBSTITUTE(SUBSTITUTE(SUBSTITUTE(SUBSTITUTE(SUBSTITUTE(LOWER(SUBSTITUTE(SUBSTITUTE(SUBSTITUTE(SUBSTITUTE(SUBSTITUTE(M4,"×","x"),"·",""),"−","-"),"–","-"),"^","")),"μ","u"),"µ","u")," ",""),"k1=",""),"k2=",""),"k3=",""),"kd=",""),"ka=",""),"k=",""),"°c",""),"m-1",""),"um",""),"mm","")) | AO4: =TRIM(SUBSTITUTE(SUBSTITUTE(SUBSTITUTE(SUBSTITUTE(SUBSTITUTE(SUBSTITUTE(SUBSTITUTE(SUBSTITUTE(SUBSTITUTE(SUBSTITUTE(SUBSTITUTE(SUBSTITUTE(SUBSTITUTE(LOWER(SUBSTITUTE(SUBSTITUTE(SUBSTITUTE(SUBSTITUTE(SUBSTITUTE(N4,"×","x"),"·",""),"−","-"),"–","-"),"^","")),"μ","u"),"µ","u")," ",""),"k1=",""),"k2=",""),"k3=",""),"kd=",""),"ka=",""),"k=",""),"°c",""),"m-1",""),"um",""),"mm","")) | AP4: =TRIM(SUBSTITUTE(SUBSTITUTE(SUBSTITUTE(SUBSTITUTE(SUBSTITUTE(SUBSTITUTE(SUBSTITUTE(SUBSTITUTE(SUBSTITUTE(SUBSTITUTE(SUBSTITUTE(SUBSTITUTE(SUBSTITUTE(LOWER(SUBSTITUTE(SUBSTITUTE(SUBSTITUTE(SUBSTITUTE(SUBSTITUTE(O4,"×","x"),"·",""),"−","-"),"–","-"),"^","")),"μ","u"),"µ","u")," ",""),"k1=",""),"k2=",""),"k3=",""),"kd=",""),"ka=",""),"k=",""),"°c",""),"m-1",""),"um",""),"mm","")) | AQ4: =TRIM(SUBSTITUTE(SUBSTITUTE(SUBSTITUTE(SUBSTITUTE(SUBSTITUTE(SUBSTITUTE(SUBSTITUTE(SUBSTITUTE(SUBSTITUTE(SUBSTITUTE(SUBSTITUTE(SUBSTITUTE(SUBSTITUTE(LOWER(SUBSTITUTE(SUBSTITUTE(SUBSTITUTE(SUBSTITUTE(SUBSTITUTE(P4,"×","x"),"·",""),"−","-"),"–","-"),"^","")),"μ","u"),"µ","u")," ",""),"k1=",""),"k2=",""),"k3=",""),"kd=",""),"ka=",""),"k=",""),"°c",""),"m-1",""),"um",""),"mm",""))
A5: 2 | B5: Bovine | C5: 4 | D5: TnC | E5: SC | F5: 4 | G5: 2.5 x 10^5 | H5: 4 | R5: =IF(J5="",0,IF(EXACT($AC5,$AK5),1,IF(IFERROR(VALUE($AC5)=VALUE($AK5),FALSE),1,0))) | S5: =IF(K5="",0,IF(EXACT($AD5,$AL5),1,IF(IFERROR(VALUE($AD5)=VALUE($AL5),FALSE),1,0))) | T5: =IF(L5="",0,IF(EXACT($AE5,$AM5),1,IF(IFERROR(VALUE($AE5)=VALUE($AM5),FALSE),1,0))) | U5: =IF(M5="",0,IF(EXACT($AF5,$AN5),1,IF(IFERROR(VALUE($AF5)=VALUE($AN5),FALSE),1,0))) | V5: =IF(N5="",0,IF(EXACT($AG5,$AO5),1,IF(IFERROR(VALUE($AG5)=VALUE($AO5),FALSE),1,0))) | W5: =IF(O5="",0,IF(EXACT($AH5,$AP5),1,IF(IFERROR(VALUE($AH5)=VALUE($AP5),FALSE),1,0))) | X5: =IF(P5="",0,IF(EXACT($AI5,$AQ5),1,IF(IFERROR(VALUE($AI5)=VALUE($AQ5),FALSE),1,0))) | Y5: =SUM(R5:X5) | AA5: =IF(Z5="",Y5,Z5) | AC5: =TRIM(SUBSTITUTE(SUBSTITUTE(SUBSTITUTE(SUBSTITUTE(SUBSTITUTE(SUBSTITUTE(SUBSTITUTE(SUBSTITUTE(SUBSTITUTE(SUBSTITUTE(SUBSTITUTE(SUBSTITUTE(SUBSTITUTE(LOWER(SUBSTITUTE(SUBSTITUTE(SUBSTITUTE(SUBSTITUTE(SUBSTITUTE(B5,"×","x"),"·",""),"−","-"),"–","-"),"^","")),"μ","u"),"µ","u")," ",""),"k1=",""),"k2=",""),"k3=",""),"kd=",""),"ka=",""),"k=",""),"°c",""),"m-1",""),"um",""),"mm","")) | AD5: =TRIM(SUBSTITUTE(SUBSTITUTE(SUBSTITUTE(SUBSTITUTE(SUBSTITUTE(SUBSTITUTE(SUBSTITUTE(SUBSTITUTE(SUBSTITUTE(SUBSTITUTE(SUBSTITUTE(SUBSTITUTE(SUBSTITUTE(LOWER(SUBSTITUTE(SUBSTITUTE(SUBSTITUTE(SUBSTITUTE(SUBSTITUTE(C5,"×","x"),"·",""),"−","-"),"–","-"),"^","")),"μ","u"),"µ","u")," ",""),"k1=",""),"k2=",""),"k3=",""),"kd=",""),"ka=",""),"k=",""),"°c",""),"m-1",""),"um",""),"mm","")) | AE5: =TRIM(SUBSTITUTE(SUBSTITUTE(SUBSTITUTE(SUBSTITUTE(SUBSTITUTE(SUBSTITUTE(SUBSTITUTE(SUBSTITUTE(SUBSTITUTE(SUBSTITUTE(SUBSTITUTE(SUBSTITUTE(SUBSTITUTE(LOWER(SUBSTITUTE(SUBSTITUTE(SUBSTITUTE(SUBSTITUTE(SUBSTITUTE(D5,"×","x"),"·",""),"−","-"),"–","-"),"^","")),"μ","u"),"µ","u")," ",""),"k1=",""),"k2=",""),"k3=",""),"kd=",""),"ka=",""),"k=",""),"°c",""),"m-1",""),"um",""),"mm","")) | AF5: =TRIM(SUBSTITUTE(SUBSTITUTE(SUBSTITUTE(SUBSTITUTE(SUBSTITUTE(SUBSTITUTE(SUBSTITUTE(SUBSTITUTE(SUBSTITUTE(SUBSTITUTE(SUBSTITUTE(SUBSTITUTE(SUBSTITUTE(LOWER(SUBSTITUTE(SUBSTITUTE(SUBSTITUTE(SUBSTITUTE(SUBSTITUTE(E5,"×","x"),"·",""),"−","-"),"–","-"),"^","")),"μ","u"),"µ","u")," ",""),"k1=",""),"k2=",""),"k3=",""),"kd=",""),"ka=",""),"k=",""),"°c",""),"m-1",""),"um",""),"mm","")) | AG5: =TRIM(SUBSTITUTE(SUBSTITUTE(SUBSTITUTE(SUBSTITUTE(SUBSTITUTE(SUBSTITUTE(SUBSTITUTE(SUBSTITUTE(SUBSTITUTE(SUBSTITUTE(SUBSTITUTE(SUBSTITUTE(SUBSTITUTE(LOWER(SUBSTITUTE(SUBSTITUTE(SUBSTITUTE(SUBSTITUTE(SUBSTITUTE(F5,"×","x"),"·",""),"−","-"),"–","-"),"^","")),"μ","u"),"µ","u")," ",""),"k1=",""),"k2=",""),"k3=",""),"kd=",""),"ka=",""),"k=",""),"°c",""),"m-1",""),"um",""),"mm","")) | AH5: =TRIM(SUBSTITUTE(SUBSTITUTE(SUBSTITUTE(SUBSTITUTE(SUBSTITUTE(SUBSTITUTE(SUBSTITUTE(SUBSTITUTE(SUBSTITUTE(SUBSTITUTE(SUBSTITUTE(SUBSTITUTE(SUBSTITUTE(LOWER(SUBSTITUTE(SUBSTITUTE(SUBSTITUTE(SUBSTITUTE(SUBSTITUTE(G5,"×","x"),"·",""),"−","-"),"–","-"),"^","")),"μ","u"),"µ","u")," ",""),"k1=",""),"k2=",""),"k3=",""),"kd=",""),"ka=",""),"k=",""),"°c",""),"m-1",""),"um",""),"mm","")) | AI5: =TRIM(SUBSTITUTE(SUBSTITUTE(SUBSTITUTE(SUBSTITUTE(SUBSTITUTE(SUBSTITUTE(SUBSTITUTE(SUBSTITUTE(SUBSTITUTE(SUBSTITUTE(SUBSTITUTE(SUBSTITUTE(SUBSTITUTE(LOWER(SUBSTITUTE(SUBSTITUTE(SUBSTITUTE(SUBSTITUTE(SUBSTITUTE(H5,"×","x"),"·",""),"−","-"),"–","-"),"^","")),"μ","u"),"µ","u")," ",""),"k1=",""),"k2=",""),"k3=",""),"kd=",""),"ka=",""),"k=",""),"°c",""),"m-1",""),"um",""),"mm","")) | AK5: =TRIM(SUBSTITUTE(SUBSTITUTE(SUBSTITUTE(SUBSTITUTE(SUBSTITUTE(SUBSTITUTE(SUBSTITUTE(SUBSTITUTE(SUBSTITUTE(SUBSTITUTE(SUBSTITUTE(SUBSTITUTE(SUBSTITUTE(LOWER(SUBSTITUTE(SUBSTITUTE(SUBSTITUTE(SUBSTITUTE(SUBSTITUTE(J5,"×","x"),"·",""),"−","-"),"–","-"),"^","")),"μ","u"),"µ","u")," ",""),"k1=",""),"k2=",""),"k3=",""),"kd=",""),"ka=",""),"k=",""),"°c",""),"m-1",""),"um",""),"mm","")) | AL5: =TRIM(SUBSTITUTE(SUBSTITUTE(SUBSTITUTE(SUBSTITUTE(SUBSTITUTE(SUBSTITUTE(SUBSTITUTE(SUBSTITUTE(SUBSTITUTE(SUBSTITUTE(SUBSTITUTE(SUBSTITUTE(SUBSTITUTE(LOWER(SUBSTITUTE(SUBSTITUTE(SUBSTITUTE(SUBSTITUTE(SUBSTITUTE(K5,"×","x"),"·",""),"−","-"),"–","-"),"^","")),"μ","u"),"µ","u")," ",""),"k1=",""),"k2=",""),"k3=",""),"kd=",""),"ka=",""),"k=",""),"°c",""),"m-1",""),"um",""),"mm","")) | AM5: =TRIM(SUBSTITUTE(SUBSTITUTE(SUBSTITUTE(SUBSTITUTE(SUBSTITUTE(SUBSTITUTE(SUBSTITUTE(SUBSTITUTE(SUBSTITUTE(SUBSTITUTE(SUBSTITUTE(SUBSTITUTE(SUBSTITUTE(LOWER(SUBSTITUTE(SUBSTITUTE(SUBSTITUTE(SUBSTITUTE(SUBSTITUTE(L5,"×","x"),"·",""),"−","-"),"–","-"),"^","")),"μ","u"),"µ","u")," ",""),"k1=",""),"k2=",""),"k3=",""),"kd=",""),"ka=",""),"k=",""),"°c",""),"m-1",""),"um",""),"mm","")) | AN5: =TRIM(SUBSTITUTE(SUBSTITUTE(SUBSTITUTE(SUBSTITUTE(SUBSTITUTE(SUBSTITUTE(SUBSTITUTE(SUBSTITUTE(SUBSTITUTE(SUBSTITUTE(SUBSTITUTE(SUBSTITUTE(SUBSTITUTE(LOWER(SUBSTITUTE(SUBSTITUTE(SUBSTITUTE(SUBSTITUTE(SUBSTITUTE(M5,"×","x"),"·",""),"−","-"),"–","-"),"^","")),"μ","u"),"µ","u")," ",""),"k1=",""),"k2=",""),"k3=",""),"kd=",""),"ka=",""),"k=",""),"°c",""),"m-1",""),"um",""),"mm","")) | AO5: =TRIM(SUBSTITUTE(SUBSTITUTE(SUBSTITUTE(SUBSTITUTE(SUBSTITUTE(SUBSTITUTE(SUBSTITUTE(SUBSTITUTE(SUBSTITUTE(SUBSTITUTE(SUBSTITUTE(SUBSTITUTE(SUBSTITUTE(LOWER(SUBSTITUTE(SUBSTITUTE(SUBSTITUTE(SUBSTITUTE(SUBSTITUTE(N5,"×","x"),"·",""),"−","-"),"–","-"),"^","")),"μ","u"),"µ","u")," ",""),"k1=",""),"k2=",""),"k3=",""),"kd=",""),"ka=",""),"k=",""),"°c",""),"m-1",""),"um",""),"mm","")) | AP5: =TRIM(SUBSTITUTE(SUBSTITUTE(SUBSTITUTE(SUBSTITUTE(SUBSTITUTE(SUBSTITUTE(SUBSTITUTE(SUBSTITUTE(SUBSTITUTE(SUBSTITUTE(SUBSTITUTE(SUBSTITUTE(SUBSTITUTE(LOWER(SUBSTITUTE(SUBSTITUTE(SUBSTITUTE(SUBSTITUTE(SUBSTITUTE(O5,"×","x"),"·",""),"−","-"),"–","-"),"^","")),"μ","u"),"µ","u")," ",""),"k1=",""),"k2=",""),"k3=",""),"kd=",""),"ka=",""),"k=",""),"°c",""),"m-1",""),"um",""),"mm","")) | AQ5: =TRIM(SUBSTITUTE(SUBSTITUTE(SUBSTITUTE(SUBSTITUTE(SUBSTITUTE(SUBSTITUTE(SUBSTITUTE(SUBSTITUTE(SUBSTITUTE(SUBSTITUTE(SUBSTITUTE(SUBSTITUTE(SUBSTITUTE(LOWER(SUBSTITUTE(SUBSTITUTE(SUBSTITUTE(SUBSTITUTE(SUBSTITUTE(P5,"×","x"),"·",""),"−","-"),"–","-"),"^","")),"μ","u"),"µ","u")," ",""),"k1=",""),"k2=",""),"k3=",""),"kd=",""),"ka=",""),"k=",""),"°c",""),"m-1",""),"um",""),"mm",""))
A6: 3 | B6: Bovine | C6: 4 | D6: TnC-TnI | E6: SC | F6: 4 | G6: 1 x 10^6 | H6: 1 | R6: =IF(J6="",0,IF(EXACT($AC6,$AK6),1,IF(IFERROR(VALUE($AC6)=VALUE($AK6),FALSE),1,0))) | S6: =IF(K6="",0,IF(EXACT($AD6,$AL6),1,IF(IFERROR(VALUE($AD6)=VALUE($AL6),FALSE),1,0))) | T6: =IF(L6="",0,IF(EXACT($AE6,$AM6),1,IF(IFERROR(VALUE($AE6)=VALUE($AM6),FALSE),1,0))) | U6: =IF(M6="",0,IF(EXACT($AF6,$AN6),1,IF(IFERROR(VALUE($AF6)=VALUE($AN6),FALSE),1,0))) | V6: =IF(N6="",0,IF(EXACT($AG6,$AO6),1,IF(IFERROR(VALUE($AG6)=VALUE($AO6),FALSE),1,0))) | W6: =IF(O6="",0,IF(EXACT($AH6,$AP6),1,IF(IFERROR(VALUE($AH6)=VALUE($AP6),FALSE),1,0))) | X6: =IF(P6="",0,IF(EXACT($AI6,$AQ6),1,IF(IFERROR(VALUE($AI6)=VALUE($AQ6),FALSE),1,0))) | Y6: =SUM(R6:X6) | AA6: =IF(Z6="",Y6,Z6) | AC6: =TRIM(SUBSTITUTE(SUBSTITUTE(SUBSTITUTE(SUBSTITUTE(SUBSTITUTE(SUBSTITUTE(SUBSTITUTE(SUBSTITUTE(SUBSTITUTE(SUBSTITUTE(SUBSTITUTE(SUBSTITUTE(SUBSTITUTE(LOWER(SUBSTITUTE(SUBSTITUTE(SUBSTITUTE(SUBSTITUTE(SUBSTITUTE(B6,"×","x"),"·",""),"−","-"),"–","-"),"^","")),"μ","u"),"µ","u")," ",""),"k1=",""),"k2=",""),"k3=",""),"kd=",""),"ka=",""),"k=",""),"°c",""),"m-1",""),"um",""),"mm","")) | AD6: =TRIM(SUBSTITUTE(SUBSTITUTE(SUBSTITUTE(SUBSTITUTE(SUBSTITUTE(SUBSTITUTE(SUBSTITUTE(SUBSTITUTE(SUBSTITUTE(SUBSTITUTE(SUBSTITUTE(SUBSTITUTE(SUBSTITUTE(LOWER(SUBSTITUTE(SUBSTITUTE(SUBSTITUTE(SUBSTITUTE(SUBSTITUTE(C6,"×","x"),"·",""),"−","-"),"–","-"),"^","")),"μ","u"),"µ","u")," ",""),"k1=",""),"k2=",""),"k3=",""),"kd=",""),"ka=",""),"k=",""),"°c",""),"m-1",""),"um",""),"mm","")) | AE6: =TRIM(SUBSTITUTE(SUBSTITUTE(SUBSTITUTE(SUBSTITUTE(SUBSTITUTE(SUBSTITUTE(SUBSTITUTE(SUBSTITUTE(SUBSTITUTE(SUBSTITUTE(SUBSTITUTE(SUBSTITUTE(SUBSTITUTE(LOWER(SUBSTITUTE(SUBSTITUTE(SUBSTITUTE(SUBSTITUTE(SUBSTITUTE(D6,"×","x"),"·",""),"−","-"),"–","-"),"^","")),"μ","u"),"µ","u")," ",""),"k1=",""),"k2=",""),"k3=",""),"kd=",""),"ka=",""),"k=",""),"°c",""),"m-1",""),"um",""),"mm","")) | AF6: =TRIM(SUBSTITUTE(SUBSTITUTE(SUBSTITUTE(SUBSTITUTE(SUBSTITUTE(SUBSTITUTE(SUBSTITUTE(SUBSTITUTE(SUBSTITUTE(SUBSTITUTE(SUBSTITUTE(SUBSTITUTE(SUBSTITUTE(LOWER(SUBSTITUTE(SUBSTITUTE(SUBSTITUTE(SUBSTITUTE(SUBSTITUTE(E6,"×","x"),"·",""),"−","-"),"–","-"),"^","")),"μ","u"),"µ","u")," ",""),"k1=",""),"k2=",""),"k3=",""),"kd=",""),"ka=",""),"k=",""),"°c",""),"m-1",""),"um",""),"mm","")) | AG6: =TRIM(SUBSTITUTE(SUBSTITUTE(SUBSTITUTE(SUBSTITUTE(SUBSTITUTE(SUBSTITUTE(SUBSTITUTE(SUBSTITUTE(SUBSTITUTE(SUBSTITUTE(SUBSTITUTE(SUBSTITUTE(SUBSTITUTE(LOWER(SUBSTITUTE(SUBSTITUTE(SUBSTITUTE(SUBSTITUTE(SUBSTITUTE(F6,"×","x"),"·",""),"−","-"),"–","-"),"^","")),"μ","u"),"µ","u")," ",""),"k1=",""),"k2=",""),"k3=",""),"kd=",""),"ka=",""),"k=",""),"°c",""),"m-1",""),"um",""),"mm","")) | AH6: =TRIM(SUBSTITUTE(SUBSTITUTE(SUBSTITUTE(SUBSTITUTE(SUBSTITUTE(SUBSTITUTE(SUBSTITUTE(SUBSTITUTE(SUBSTITUTE(SUBSTITUTE(SUBSTITUTE(SUBSTITUTE(SUBSTITUTE(LOWER(SUBSTITUTE(SUBSTITUTE(SUBSTITUTE(SUBSTITUTE(SUBSTITUTE(G6,"×","x"),"·",""),"−","-"),"–","-"),"^","")),"μ","u"),"µ","u")," ",""),"k1=",""),"k2=",""),"k3=",""),"kd=",""),"ka=",""),"k=",""),"°c",""),"m-1",""),"um",""),"mm","")) | AI6: =TRIM(SUBSTITUTE(SUBSTITUTE(SUBSTITUTE(SUBSTITUTE(SUBSTITUTE(SUBSTITUTE(SUBSTITUTE(SUBSTITUTE(SUBSTITUTE(SUBSTITUTE(SUBSTITUTE(SUBSTITUTE(SUBSTITUTE(LOWER(SUBSTITUTE(SUBSTITUTE(SUBSTITUTE(SUBSTITUTE(SUBSTITUTE(H6,"×","x"),"·",""),"−","-"),"–","-"),"^","")),"μ","u"),"µ","u")," ",""),"k1=",""),"k2=",""),"k3=",""),"kd=",""),"ka=",""),"k=",""),"°c",""),"m-1",""),"um",""),"mm","")) | AK6: =TRIM(SUBSTITUTE(SUBSTITUTE(SUBSTITUTE(SUBSTITUTE(SUBSTITUTE(SUBSTITUTE(SUBSTITUTE(SUBSTITUTE(SUBSTITUTE(SUBSTITUTE(SUBSTITUTE(SUBSTITUTE(SUBSTITUTE(LOWER(SUBSTITUTE(SUBSTITUTE(SUBSTITUTE(SUBSTITUTE(SUBSTITUTE(J6,"×","x"),"·",""),"−","-"),"–","-"),"^","")),"μ","u"),"µ","u")," ",""),"k1=",""),"k2=",""),"k3=",""),"kd=",""),"ka=",""),"k=",""),"°c",""),"m-1",""),"um",""),"mm","")) | AL6: =TRIM(SUBSTITUTE(SUBSTITUTE(SUBSTITUTE(SUBSTITUTE(SUBSTITUTE(SUBSTITUTE(SUBSTITUTE(SUBSTITUTE(SUBSTITUTE(SUBSTITUTE(SUBSTITUTE(SUBSTITUTE(SUBSTITUTE(LOWER(SUBSTITUTE(SUBSTITUTE(SUBSTITUTE(SUBSTITUTE(SUBSTITUTE(K6,"×","x"),"·",""),"−","-"),"–","-"),"^","")),"μ","u"),"µ","u")," ",""),"k1=",""),"k2=",""),"k3=",""),"kd=",""),"ka=",""),"k=",""),"°c",""),"m-1",""),"um",""),"mm","")) | AM6: =TRIM(SUBSTITUTE(SUBSTITUTE(SUBSTITUTE(SUBSTITUTE(SUBSTITUTE(SUBSTITUTE(SUBSTITUTE(SUBSTITUTE(SUBSTITUTE(SUBSTITUTE(SUBSTITUTE(SUBSTITUTE(SUBSTITUTE(LOWER(SUBSTITUTE(SUBSTITUTE(SUBSTITUTE(SUBSTITUTE(SUBSTITUTE(L6,"×","x"),"·",""),"−","-"),"–","-"),"^","")),"μ","u"),"µ","u")," ",""),"k1=",""),"k2=",""),"k3=",""),"kd=",""),"ka=",""),"k=",""),"°c",""),"m-1",""),"um",""),"mm","")) | AN6: =TRIM(SUBSTITUTE(SUBSTITUTE(SUBSTITUTE(SUBSTITUTE(SUBSTITUTE(SUBSTITUTE(SUBSTITUTE(SUBSTITUTE(SUBSTITUTE(SUBSTITUTE(SUBSTITUTE(SUBSTITUTE(SUBSTITUTE(LOWER(SUBSTITUTE(SUBSTITUTE(SUBSTITUTE(SUBSTITUTE(SUBSTITUTE(M6,"×","x"),"·",""),"−","-"),"–","-"),"^","")),"μ","u"),"µ","u")," ",""),"k1=",""),"k2=",""),"k3=",""),"kd=",""),"ka=",""),"k=",""),"°c",""),"m-1",""),"um",""),"mm","")) | AO6: =TRIM(SUBSTITUTE(SUBSTITUTE(SUBSTITUTE(SUBSTITUTE(SUBSTITUTE(SUBSTITUTE(SUBSTITUTE(SUBSTITUTE(SUBSTITUTE(SUBSTITUTE(SUBSTITUTE(SUBSTITUTE(SUBSTITUTE(LOWER(SUBSTITUTE(SUBSTITUTE(SUBSTITUTE(SUBSTITUTE(SUBSTITUTE(N6,"×","x"),"·",""),"−","-"),"–","-"),"^","")),"μ","u"),"µ","u")," ",""),"k1=",""),"k2=",""),"k3=",""),"kd=",""),"ka=",""),"k=",""),"°c",""),"m-1",""),"um",""),"mm","")) | AP6: =TRIM(SUBSTITUTE(SUBSTITUTE(SUBSTITUTE(SUBSTITUTE(SUBSTITUTE(SUBSTITUTE(SUBSTITUTE(SUBSTITUTE(SUBSTITUTE(SUBSTITUTE(SUBSTITUTE(SUBSTITUTE(SUBSTITUTE(LOWER(SUBSTITUTE(SUBSTITUTE(SUBSTITUTE(SUBSTITUTE(SUBSTITUTE(O6,"×","x"),"·",""),"−","-"),"–","-"),"^","")),"μ","u"),"µ","u")," ",""),"k1=",""),"k2=",""),"k3=",""),"kd=",""),"ka=",""),"k=",""),"°c",""),"m-1",""),"um",""),"mm","")) | AQ6: =TRIM(SUBSTITUTE(SUBSTITUTE(SUBSTITUTE(SUBSTITUTE(SUBSTITUTE(SUBSTITUTE(SUBSTITUTE(SUBSTITUTE(SUBSTITUTE(SUBSTITUTE(SUBSTITUTE(SUBSTITUTE(SUBSTITUTE(LOWER(SUBSTITUTE(SUBSTITUTE(SUBSTITUTE(SUBSTITUTE(SUBSTITUTE(P6,"×","x"),"·",""),"−","-"),"–","-"),"^","")),"μ","u"),"µ","u")," ",""),"k1=",""),"k2=",""),"k3=",""),"kd=",""),"ka=",""),"k=",""),"°c",""),"m-1",""),"um",""),"mm",""))
A7: 4 | B7: Bovine | C7: 4 | D7: TnC-TnI | E7: SC | F7: None | G7: 1 x 10^6 | H7: 1 | R7: =IF(J7="",0,IF(EXACT($AC7,$AK7),1,IF(IFERROR(VALUE($AC7)=VALUE($AK7),FALSE),1,0))) | S7: =IF(K7="",0,IF(EXACT($AD7,$AL7),1,IF(IFERROR(VALUE($AD7)=VALUE($AL7),FALSE),1,0))) | T7: =IF(L7="",0,IF(EXACT($AE7,$AM7),1,IF(IFERROR(VALUE($AE7)=VALUE($AM7),FALSE),1,0))) | U7: =IF(M7="",0,IF(EXACT($AF7,$AN7),1,IF(IFERROR(VALUE($AF7)=VALUE($AN7),FALSE),1,0))) | V7: =IF(N7="",0,IF(EXACT($AG7,$AO7),1,IF(IFERROR(VALUE($AG7)=VALUE($AO7),FALSE),1,0))) | W7: =IF(O7="",0,IF(EXACT($AH7,$AP7),1,IF(IFERROR(VALUE($AH7)=VALUE($AP7),FALSE),1,0))) | X7: =IF(P7="",0,IF(EXACT($AI7,$AQ7),1,IF(IFERROR(VALUE($AI7)=VALUE($AQ7),FALSE),1,0))) | Y7: =SUM(R7:X7) | AA7: =IF(Z7="",Y7,Z7) | AC7: =TRIM(SUBSTITUTE(SUBSTITUTE(SUBSTITUTE(SUBSTITUTE(SUBSTITUTE(SUBSTITUTE(SUBSTITUTE(SUBSTITUTE(SUBSTITUTE(SUBSTITUTE(SUBSTITUTE(SUBSTITUTE(SUBSTITUTE(LOWER(SUBSTITUTE(SUBSTITUTE(SUBSTITUTE(SUBSTITUTE(SUBSTITUTE(B7,"×","x"),"·",""),"−","-"),"–","-"),"^","")),"μ","u"),"µ","u")," ",""),"k1=",""),"k2=",""),"k3=",""),"kd=",""),"ka=",""),"k=",""),"°c",""),"m-1",""),"um",""),"mm","")) | AD7: =TRIM(SUBSTITUTE(SUBSTITUTE(SUBSTITUTE(SUBSTITUTE(SUBSTITUTE(SUBSTITUTE(SUBSTITUTE(SUBSTITUTE(SUBSTITUTE(SUBSTITUTE(SUBSTITUTE(SUBSTITUTE(SUBSTITUTE(LOWER(SUBSTITUTE(SUBSTITUTE(SUBSTITUTE(SUBSTITUTE(SUBSTITUTE(C7,"×","x"),"·",""),"−","-"),"–","-"),"^","")),"μ","u"),"µ","u")," ",""),"k1=",""),"k2=",""),"k3=",""),"kd=",""),"ka=",""),"k=",""),"°c",""),"m-1",""),"um",""),"mm","")) | AE7: =TRIM(SUBSTITUTE(SUBSTITUTE(SUBSTITUTE(SUBSTITUTE(SUBSTITUTE(SUBSTITUTE(SUBSTITUTE(SUBSTITUTE(SUBSTITUTE(SUBSTITUTE(SUBSTITUTE(SUBSTITUTE(SUBSTITUTE(LOWER(SUBSTITUTE(SUBSTITUTE(SUBSTITUTE(SUBSTITUTE(SUBSTITUTE(D7,"×","x"),"·",""),"−","-"),"–","-"),"^","")),"μ","u"),"µ","u")," ",""),"k1=",""),"k2=",""),"k3=",""),"kd=",""),"ka=",""),"k=",""),"°c",""),"m-1",""),"um",""),"mm","")) | AF7: =TRIM(SUBSTITUTE(SUBSTITUTE(SUBSTITUTE(SUBSTITUTE(SUBSTITUTE(SUBSTITUTE(SUBSTITUTE(SUBSTITUTE(SUBSTITUTE(SUBSTITUTE(SUBSTITUTE(SUBSTITUTE(SUBSTITUTE(LOWER(SUBSTITUTE(SUBSTITUTE(SUBSTITUTE(SUBSTITUTE(SUBSTITUTE(E7,"×","x"),"·",""),"−","-"),"–","-"),"^","")),"μ","u"),"µ","u")," ",""),"k1=",""),"k2=",""),"k3=",""),"kd=",""),"ka=",""),"k=",""),"°c",""),"m-1",""),"um",""),"mm","")) | AG7: =TRIM(SUBSTITUTE(SUBSTITUTE(SUBSTITUTE(SUBSTITUTE(SUBSTITUTE(SUBSTITUTE(SUBSTITUTE(SUBSTITUTE(SUBSTITUTE(SUBSTITUTE(SUBSTITUTE(SUBSTITUTE(SUBSTITUTE(LOWER(SUBSTITUTE(SUBSTITUTE(SUBSTITUTE(SUBSTITUTE(SUBSTITUTE(F7,"×","x"),"·",""),"−","-"),"–","-"),"^","")),"μ","u"),"µ","u")," ",""),"k1=",""),"k2=",""),"k3=",""),"kd=",""),"ka=",""),"k=",""),"°c",""),"m-1",""),"um",""),"mm","")) | AH7: =TRIM(SUBSTITUTE(SUBSTITUTE(SUBSTITUTE(SUBSTITUTE(SUBSTITUTE(SUBSTITUTE(SUBSTITUTE(SUBSTITUTE(SUBSTITUTE(SUBSTITUTE(SUBSTITUTE(SUBSTITUTE(SUBSTITUTE(LOWER(SUBSTITUTE(SUBSTITUTE(SUBSTITUTE(SUBSTITUTE(SUBSTITUTE(G7,"×","x"),"·",""),"−","-"),"–","-"),"^","")),"μ","u"),"µ","u")," ",""),"k1=",""),"k2=",""),"k3=",""),"kd=",""),"ka=",""),"k=",""),"°c",""),"m-1",""),"um",""),"mm","")) | AI7: =TRIM(SUBSTITUTE(SUBSTITUTE(SUBSTITUTE(SUBSTITUTE(SUBSTITUTE(SUBSTITUTE(SUBSTITUTE(SUBSTITUTE(SUBSTITUTE(SUBSTITUTE(SUBSTITUTE(SUBSTITUTE(SUBSTITUTE(LOWER(SUBSTITUTE(SUBSTITUTE(SUBSTITUTE(SUBSTITUTE(SUBSTITUTE(H7,"×","x"),"·",""),"−","-"),"–","-"),"^","")),"μ","u"),"µ","u")," ",""),"k1=",""),"k2=",""),"k3=",""),"kd=",""),"ka=",""),"k=",""),"°c",""),"m-1",""),"um",""),"mm","")) | AK7: =TRIM(SUBSTITUTE(SUBSTITUTE(SUBSTITUTE(SUBSTITUTE(SUBSTITUTE(SUBSTITUTE(SUBSTITUTE(SUBSTITUTE(SUBSTITUTE(SUBSTITUTE(SUBSTITUTE(SUBSTITUTE(SUBSTITUTE(LOWER(SUBSTITUTE(SUBSTITUTE(SUBSTITUTE(SUBSTITUTE(SUBSTITUTE(J7,"×","x"),"·",""),"−","-"),"–","-"),"^","")),"μ","u"),"µ","u")," ",""),"k1=",""),"k2=",""),"k3=",""),"kd=",""),"ka=",""),"k=",""),"°c",""),"m-1",""),"um",""),"mm","")) | AL7: =TRIM(SUBSTITUTE(SUBSTITUTE(SUBSTITUTE(SUBSTITUTE(SUBSTITUTE(SUBSTITUTE(SUBSTITUTE(SUBSTITUTE(SUBSTITUTE(SUBSTITUTE(SUBSTITUTE(SUBSTITUTE(SUBSTITUTE(LOWER(SUBSTITUTE(SUBSTITUTE(SUBSTITUTE(SUBSTITUTE(SUBSTITUTE(K7,"×","x"),"·",""),"−","-"),"–","-"),"^","")),"μ","u"),"µ","u")," ",""),"k1=",""),"k2=",""),"k3=",""),"kd=",""),"ka=",""),"k=",""),"°c",""),"m-1",""),"um",""),"mm","")) | AM7: =TRIM(SUBSTITUTE(SUBSTITUTE(SUBSTITUTE(SUBSTITUTE(SUBSTITUTE(SUBSTITUTE(SUBSTITUTE(SUBSTITUTE(SUBSTITUTE(SUBSTITUTE(SUBSTITUTE(SUBSTITUTE(SUBSTITUTE(LOWER(SUBSTITUTE(SUBSTITUTE(SUBSTITUTE(SUBSTITUTE(SUBSTITUTE(L7,"×","x"),"·",""),"−","-"),"–","-"),"^","")),"μ","u"),"µ","u")," ",""),"k1=",""),"k2=",""),"k3=",""),"kd=",""),"ka=",""),"k=",""),"°c",""),"m-1",""),"um",""),"mm","")) | AN7: =TRIM(SUBSTITUTE(SUBSTITUTE(SUBSTITUTE(SUBSTITUTE(SUBSTITUTE(SUBSTITUTE(SUBSTITUTE(SUBSTITUTE(SUBSTITUTE(SUBSTITUTE(SUBSTITUTE(SUBSTITUTE(SUBSTITUTE(LOWER(SUBSTITUTE(SUBSTITUTE(SUBSTITUTE(SUBSTITUTE(SUBSTITUTE(M7,"×","x"),"·",""),"−","-"),"–","-"),"^","")),"μ","u"),"µ","u")," ",""),"k1=",""),"k2=",""),"k3=",""),"kd=",""),"ka=",""),"k=",""),"°c",""),"m-1",""),"um",""),"mm","")) | AO7: =TRIM(SUBSTITUTE(SUBSTITUTE(SUBSTITUTE(SUBSTITUTE(SUBSTITUTE(SUBSTITUTE(SUBSTITUTE(SUBSTITUTE(SUBSTITUTE(SUBSTITUTE(SUBSTITUTE(SUBSTITUTE(SUBSTITUTE(LOWER(SUBSTITUTE(SUBSTITUTE(SUBSTITUTE(SUBSTITUTE(SUBSTITUTE(N7,"×","x"),"·",""),"−","-"),"–","-"),"^","")),"μ","u"),"µ","u")," ",""),"k1=",""),"k2=",""),"k3=",""),"kd=",""),"ka=",""),"k=",""),"°c",""),"m-1",""),"um",""),"mm","")) | AP7: =TRIM(SUBSTITUTE(SUBSTITUTE(SUBSTITUTE(SUBSTITUTE(SUBSTITUTE(SUBSTITUTE(SUBSTITUTE(SUBSTITUTE(SUBSTITUTE(SUBSTITUTE(SUBSTITUTE(SUBSTITUTE(SUBSTITUTE(LOWER(SUBSTITUTE(SUBSTITUTE(SUBSTITUTE(SUBSTITUTE(SUBSTITUTE(O7,"×","x"),"·",""),"−","-"),"–","-"),"^","")),"μ","u"),"µ","u")," ",""),"k1=",""),"k2=",""),"k3=",""),"kd=",""),"ka=",""),"k=",""),"°c",""),"m-1",""),"um",""),"mm","")) | AQ7: =TRIM(SUBSTITUTE(SUBSTITUTE(SUBSTITUTE(SUBSTITUTE(SUBSTITUTE(SUBSTITUTE(SUBSTITUTE(SUBSTITUTE(SUBSTITUTE(SUBSTITUTE(SUBSTITUTE(SUBSTITUTE(SUBSTITUTE(LOWER(SUBSTITUTE(SUBSTITUTE(SUBSTITUTE(SUBSTITUTE(SUBSTITUTE(P7,"×","x"),"·",""),"−","-"),"–","-"),"^","")),"μ","u"),"µ","u")," ",""),"k1=",""),"k2=",""),"k3=",""),"kd=",""),"ka=",""),"k=",""),"°c",""),"m-1",""),"um",""),"mm",""))
A8: 5 | B8: Bovine | C8: 4 | D8: Tn | E8: SC | F8: None | G8: 2.5 x 10^6 | H8: 0.4 | R8: =IF(J8="",0,IF(EXACT($AC8,$AK8),1,IF(IFERROR(VALUE($AC8)=VALUE($AK8),FALSE),1,0))) | S8: =IF(K8="",0,IF(EXACT($AD8,$AL8),1,IF(IFERROR(VALUE($AD8)=VALUE($AL8),FALSE),1,0))) | T8: =IF(L8="",0,IF(EXACT($AE8,$AM8),1,IF(IFERROR(VALUE($AE8)=VALUE($AM8),FALSE),1,0))) | U8: =IF(M8="",0,IF(EXACT($AF8,$AN8),1,IF(IFERROR(VALUE($AF8)=VALUE($AN8),FALSE),1,0))) | V8: =IF(N8="",0,IF(EXACT($AG8,$AO8),1,IF(IFERROR(VALUE($AG8)=VALUE($AO8),FALSE),1,0))) | W8: =IF(O8="",0,IF(EXACT($AH8,$AP8),1,IF(IFERROR(VALUE($AH8)=VALUE($AP8),FALSE),1,0))) | X8: =IF(P8="",0,IF(EXACT($AI8,$AQ8),1,IF(IFERROR(VALUE($AI8)=VALUE($AQ8),FALSE),1,0))) | Y8: =SUM(R8:X8) | AA8: =IF(Z8="",Y8,Z8) | AC8: =TRIM(SUBSTITUTE(SUBSTITUTE(SUBSTITUTE(SUBSTITUTE(SUBSTITUTE(SUBSTITUTE(SUBSTITUTE(SUBSTITUTE(SUBSTITUTE(SUBSTITUTE(SUBSTITUTE(SUBSTITUTE(SUBSTITUTE(LOWER(SUBSTITUTE(SUBSTITUTE(SUBSTITUTE(SUBSTITUTE(SUBSTITUTE(B8,"×","x"),"·",""),"−","-"),"–","-"),"^","")),"μ","u"),"µ","u")," ",""),"k1=",""),"k2=",""),"k3=",""),"kd=",""),"ka=",""),"k=",""),"°c",""),"m-1",""),"um",""),"mm","")) | AD8: =TRIM(SUBSTITUTE(SUBSTITUTE(SUBSTITUTE(SUBSTITUTE(SUBSTITUTE(SUBSTITUTE(SUBSTITUTE(SUBSTITUTE(SUBSTITUTE(SUBSTITUTE(SUBSTITUTE(SUBSTITUTE(SUBSTITUTE(LOWER(SUBSTITUTE(SUBSTITUTE(SUBSTITUTE(SUBSTITUTE(SUBSTITUTE(C8,"×","x"),"·",""),"−","-"),"–","-"),"^","")),"μ","u"),"µ","u")," ",""),"k1=",""),"k2=",""),"k3=",""),"kd=",""),"ka=",""),"k=",""),"°c",""),"m-1",""),"um",""),"mm","")) | AE8: =TRIM(SUBSTITUTE(SUBSTITUTE(SUBSTITUTE(SUBSTITUTE(SUBSTITUTE(SUBSTITUTE(SUBSTITUTE(SUBSTITUTE(SUBSTITUTE(SUBSTITUTE(SUBSTITUTE(SUBSTITUTE(SUBSTITUTE(LOWER(SUBSTITUTE(SUBSTITUTE(SUBSTITUTE(SUBSTITUTE(SUBSTITUTE(D8,"×","x"),"·",""),"−","-"),"–","-"),"^","")),"μ","u"),"µ","u")," ",""),"k1=",""),"k2=",""),"k3=",""),"kd=",""),"ka=",""),"k=",""),"°c",""),"m-1",""),"um",""),"mm","")) | AF8: =TRIM(SUBSTITUTE(SUBSTITUTE(SUBSTITUTE(SUBSTITUTE(SUBSTITUTE(SUBSTITUTE(SUBSTITUTE(SUBSTITUTE(SUBSTITUTE(SUBSTITUTE(SUBSTITUTE(SUBSTITUTE(SUBSTITUTE(LOWER(SUBSTITUTE(SUBSTITUTE(SUBSTITUTE(SUBSTITUTE(SUBSTITUTE(E8,"×","x"),"·",""),"−","-"),"–","-"),"^","")),"μ","u"),"µ","u")," ",""),"k1=",""),"k2=",""),"k3=",""),"kd=",""),"ka=",""),"k=",""),"°c",""),"m-1",""),"um",""),"mm","")) | AG8: =TRIM(SUBSTITUTE(SUBSTITUTE(SUBSTITUTE(SUBSTITUTE(SUBSTITUTE(SUBSTITUTE(SUBSTITUTE(SUBSTITUTE(SUBSTITUTE(SUBSTITUTE(SUBSTITUTE(SUBSTITUTE(SUBSTITUTE(LOWER(SUBSTITUTE(SUBSTITUTE(SUBSTITUTE(SUBSTITUTE(SUBSTITUTE(F8,"×","x"),"·",""),"−","-"),"–","-"),"^","")),"μ","u"),"µ","u")," ",""),"k1=",""),"k2=",""),"k3=",""),"kd=",""),"ka=",""),"k=",""),"°c",""),"m-1",""),"um",""),"mm","")) | AH8: =TRIM(SUBSTITUTE(SUBSTITUTE(SUBSTITUTE(SUBSTITUTE(SUBSTITUTE(SUBSTITUTE(SUBSTITUTE(SUBSTITUTE(SUBSTITUTE(SUBSTITUTE(SUBSTITUTE(SUBSTITUTE(SUBSTITUTE(LOWER(SUBSTITUTE(SUBSTITUTE(SUBSTITUTE(SUBSTITUTE(SUBSTITUTE(G8,"×","x"),"·",""),"−","-"),"–","-"),"^","")),"μ","u"),"µ","u")," ",""),"k1=",""),"k2=",""),"k3=",""),"kd=",""),"ka=",""),"k=",""),"°c",""),"m-1",""),"um",""),"mm","")) | AI8: =TRIM(SUBSTITUTE(SUBSTITUTE(SUBSTITUTE(SUBSTITUTE(SUBSTITUTE(SUBSTITUTE(SUBSTITUTE(SUBSTITUTE(SUBSTITUTE(SUBSTITUTE(SUBSTITUTE(SUBSTITUTE(SUBSTITUTE(LOWER(SUBSTITUTE(SUBSTITUTE(SUBSTITUTE(SUBSTITUTE(SUBSTITUTE(H8,"×","x"),"·",""),"−","-"),"–","-"),"^","")),"μ","u"),"µ","u")," ",""),"k1=",""),"k2=",""),"k3=",""),"kd=",""),"ka=",""),"k=",""),"°c",""),"m-1",""),"um",""),"mm","")) | AK8: =TRIM(SUBSTITUTE(SUBSTITUTE(SUBSTITUTE(SUBSTITUTE(SUBSTITUTE(SUBSTITUTE(SUBSTITUTE(SUBSTITUTE(SUBSTITUTE(SUBSTITUTE(SUBSTITUTE(SUBSTITUTE(SUBSTITUTE(LOWER(SUBSTITUTE(SUBSTITUTE(SUBSTITUTE(SUBSTITUTE(SUBSTITUTE(J8,"×","x"),"·",""),"−","-"),"–","-"),"^","")),"μ","u"),"µ","u")," ",""),"k1=",""),"k2=",""),"k3=",""),"kd=",""),"ka=",""),"k=",""),"°c",""),"m-1",""),"um",""),"mm","")) | AL8: =TRIM(SUBSTITUTE(SUBSTITUTE(SUBSTITUTE(SUBSTITUTE(SUBSTITUTE(SUBSTITUTE(SUBSTITUTE(SUBSTITUTE(SUBSTITUTE(SUBSTITUTE(SUBSTITUTE(SUBSTITUTE(SUBSTITUTE(LOWER(SUBSTITUTE(SUBSTITUTE(SUBSTITUTE(SUBSTITUTE(SUBSTITUTE(K8,"×","x"),"·",""),"−","-"),"–","-"),"^","")),"μ","u"),"µ","u")," ",""),"k1=",""),"k2=",""),"k3=",""),"kd=",""),"ka=",""),"k=",""),"°c",""),"m-1",""),"um",""),"mm","")) | AM8: =TRIM(SUBSTITUTE(SUBSTITUTE(SUBSTITUTE(SUBSTITUTE(SUBSTITUTE(SUBSTITUTE(SUBSTITUTE(SUBSTITUTE(SUBSTITUTE(SUBSTITUTE(SUBSTITUTE(SUBSTITUTE(SUBSTITUTE(LOWER(SUBSTITUTE(SUBSTITUTE(SUBSTITUTE(SUBSTITUTE(SUBSTITUTE(L8,"×","x"),"·",""),"−","-"),"–","-"),"^","")),"μ","u"),"µ","u")," ",""),"k1=",""),"k2=",""),"k3=",""),"kd=",""),"ka=",""),"k=",""),"°c",""),"m-1",""),"um",""),"mm","")) | AN8: =TRIM(SUBSTITUTE(SUBSTITUTE(SUBSTITUTE(SUBSTITUTE(SUBSTITUTE(SUBSTITUTE(SUBSTITUTE(SUBSTITUTE(SUBSTITUTE(SUBSTITUTE(SUBSTITUTE(SUBSTITUTE(SUBSTITUTE(LOWER(SUBSTITUTE(SUBSTITUTE(SUBSTITUTE(SUBSTITUTE(SUBSTITUTE(M8,"×","x"),"·",""),"−","-"),"–","-"),"^","")),"μ","u"),"µ","u")," ",""),"k1=",""),"k2=",""),"k3=",""),"kd=",""),"ka=",""),"k=",""),"°c",""),"m-1",""),"um",""),"mm","")) | AO8: =TRIM(SUBSTITUTE(SUBSTITUTE(SUBSTITUTE(SUBSTITUTE(SUBSTITUTE(SUBSTITUTE(SUBSTITUTE(SUBSTITUTE(SUBSTITUTE(SUBSTITUTE(SUBSTITUTE(SUBSTITUTE(SUBSTITUTE(LOWER(SUBSTITUTE(SUBSTITUTE(SUBSTITUTE(SUBSTITUTE(SUBSTITUTE(N8,"×","x"),"·",""),"−","-"),"–","-"),"^","")),"μ","u"),"µ","u")," ",""),"k1=",""),"k2=",""),"k3=",""),"kd=",""),"ka=",""),"k=",""),"°c",""),"m-1",""),"um",""),"mm","")) | AP8: =TRIM(SUBSTITUTE(SUBSTITUTE(SUBSTITUTE(SUBSTITUTE(SUBSTITUTE(SUBSTITUTE(SUBSTITUTE(SUBSTITUTE(SUBSTITUTE(SUBSTITUTE(SUBSTITUTE(SUBSTITUTE(SUBSTITUTE(LOWER(SUBSTITUTE(SUBSTITUTE(SUBSTITUTE(SUBSTITUTE(SUBSTITUTE(O8,"×","x"),"·",""),"−","-"),"–","-"),"^","")),"μ","u"),"µ","u")," ",""),"k1=",""),"k2=",""),"k3=",""),"kd=",""),"ka=",""),"k=",""),"°c",""),"m-1",""),"um",""),"mm","")) | AQ8: =TRIM(SUBSTITUTE(SUBSTITUTE(SUBSTITUTE(SUBSTITUTE(SUBSTITUTE(SUBSTITUTE(SUBSTITUTE(SUBSTITUTE(SUBSTITUTE(SUBSTITUTE(SUBSTITUTE(SUBSTITUTE(SUBSTITUTE(LOWER(SUBSTITUTE(SUBSTITUTE(SUBSTITUTE(SUBSTITUTE(SUBSTITUTE(P8,"×","x"),"·",""),"−","-"),"–","-"),"^","")),"μ","u"),"µ","u")," ",""),"k1=",""),"k2=",""),"k3=",""),"kd=",""),"ka=",""),"k=",""),"°c",""),"m-1",""),"um",""),"mm",""))
A9: 6 | B9: Bovine | C9: 4 | D9: Tn | E9: SC | F9: 4 | G9: 2.5 x 10^6 | H9: 0.4 | R9: =IF(J9="",0,IF(EXACT($AC9,$AK9),1,IF(IFERROR(VALUE($AC9)=VALUE($AK9),FALSE),1,0))) | S9: =IF(K9="",0,IF(EXACT($AD9,$AL9),1,IF(IFERROR(VALUE($AD9)=VALUE($AL9),FALSE),1,0))) | T9: =IF(L9="",0,IF(EXACT($AE9,$AM9),1,IF(IFERROR(VALUE($AE9)=VALUE($AM9),FALSE),1,0))) | U9: =IF(M9="",0,IF(EXACT($AF9,$AN9),1,IF(IFERROR(VALUE($AF9)=VALUE($AN9),FALSE),1,0))) | V9: =IF(N9="",0,IF(EXACT($AG9,$AO9),1,IF(IFERROR(VALUE($AG9)=VALUE($AO9),FALSE),1,0))) | W9: =IF(O9="",0,IF(EXACT($AH9,$AP9),1,IF(IFERROR(VALUE($AH9)=VALUE($AP9),FALSE),1,0))) | X9: =IF(P9="",0,IF(EXACT($AI9,$AQ9),1,IF(IFERROR(VALUE($AI9)=VALUE($AQ9),FALSE),1,0))) | Y9: =SUM(R9:X9) | AA9: =IF(Z9="",Y9,Z9) | AC9: =TRIM(SUBSTITUTE(SUBSTITUTE(SUBSTITUTE(SUBSTITUTE(SUBSTITUTE(SUBSTITUTE(SUBSTITUTE(SUBSTITUTE(SUBSTITUTE(SUBSTITUTE(SUBSTITUTE(SUBSTITUTE(SUBSTITUTE(LOWER(SUBSTITUTE(SUBSTITUTE(SUBSTITUTE(SUBSTITUTE(SUBSTITUTE(B9,"×","x"),"·",""),"−","-"),"–","-"),"^","")),"μ","u"),"µ","u")," ",""),"k1=",""),"k2=",""),"k3=",""),"kd=",""),"ka=",""),"k=",""),"°c",""),"m-1",""),"um",""),"mm","")) | AD9: =TRIM(SUBSTITUTE(SUBSTITUTE(SUBSTITUTE(SUBSTITUTE(SUBSTITUTE(SUBSTITUTE(SUBSTITUTE(SUBSTITUTE(SUBSTITUTE(SUBSTITUTE(SUBSTITUTE(SUBSTITUTE(SUBSTITUTE(LOWER(SUBSTITUTE(SUBSTITUTE(SUBSTITUTE(SUBSTITUTE(SUBSTITUTE(C9,"×","x"),"·",""),"−","-"),"–","-"),"^","")),"μ","u"),"µ","u")," ",""),"k1=",""),"k2=",""),"k3=",""),"kd=",""),"ka=",""),"k=",""),"°c",""),"m-1",""),"um",""),"mm","")) | AE9: =TRIM(SUBSTITUTE(SUBSTITUTE(SUBSTITUTE(SUBSTITUTE(SUBSTITUTE(SUBSTITUTE(SUBSTITUTE(SUBSTITUTE(SUBSTITUTE(SUBSTITUTE(SUBSTITUTE(SUBSTITUTE(SUBSTITUTE(LOWER(SUBSTITUTE(SUBSTITUTE(SUBSTITUTE(SUBSTITUTE(SUBSTITUTE(D9,"×","x"),"·",""),"−","-"),"–","-"),"^","")),"μ","u"),"µ","u")," ",""),"k1=",""),"k2=",""),"k3=",""),"kd=",""),"ka=",""),"k=",""),"°c",""),"m-1",""),"um",""),"mm","")) | AF9: =TRIM(SUBSTITUTE(SUBSTITUTE(SUBSTITUTE(SUBSTITUTE(SUBSTITUTE(SUBSTITUTE(SUBSTITUTE(SUBSTITUTE(SUBSTITUTE(SUBSTITUTE(SUBSTITUTE(SUBSTITUTE(SUBSTITUTE(LOWER(SUBSTITUTE(SUBSTITUTE(SUBSTITUTE(SUBSTITUTE(SUBSTITUTE(E9,"×","x"),"·",""),"−","-"),"–","-"),"^","")),"μ","u"),"µ","u")," ",""),"k1=",""),"k2=",""),"k3=",""),"kd=",""),"ka=",""),"k=",""),"°c",""),"m-1",""),"um",""),"mm","")) | AG9: =TRIM(SUBSTITUTE(SUBSTITUTE(SUBSTITUTE(SUBSTITUTE(SUBSTITUTE(SUBSTITUTE(SUBSTITUTE(SUBSTITUTE(SUBSTITUTE(SUBSTITUTE(SUBSTITUTE(SUBSTITUTE(SUBSTITUTE(LOWER(SUBSTITUTE(SUBSTITUTE(SUBSTITUTE(SUBSTITUTE(SUBSTITUTE(F9,"×","x"),"·",""),"−","-"),"–","-"),"^","")),"μ","u"),"µ","u")," ",""),"k1=",""),"k2=",""),"k3=",""),"kd=",""),"ka=",""),"k=",""),"°c",""),"m-1",""),"um",""),"mm","")) | AH9: =TRIM(SUBSTITUTE(SUBSTITUTE(SUBSTITUTE(SUBSTITUTE(SUBSTITUTE(SUBSTITUTE(SUBSTITUTE(SUBSTITUTE(SUBSTITUTE(SUBSTITUTE(SUBSTITUTE(SUBSTITUTE(SUBSTITUTE(LOWER(SUBSTITUTE(SUBSTITUTE(SUBSTITUTE(SUBSTITUTE(SUBSTITUTE(G9,"×","x"),"·",""),"−","-"),"–","-"),"^","")),"μ","u"),"µ","u")," ",""),"k1=",""),"k2=",""),"k3=",""),"kd=",""),"ka=",""),"k=",""),"°c",""),"m-1",""),"um",""),"mm","")) | AI9: =TRIM(SUBSTITUTE(SUBSTITUTE(SUBSTITUTE(SUBSTITUTE(SUBSTITUTE(SUBSTITUTE(SUBSTITUTE(SUBSTITUTE(SUBSTITUTE(SUBSTITUTE(SUBSTITUTE(SUBSTITUTE(SUBSTITUTE(LOWER(SUBSTITUTE(SUBSTITUTE(SUBSTITUTE(SUBSTITUTE(SUBSTITUTE(H9,"×","x"),"·",""),"−","-"),"–","-"),"^","")),"μ","u"),"µ","u")," ",""),"k1=",""),"k2=",""),"k3=",""),"kd=",""),"ka=",""),"k=",""),"°c",""),"m-1",""),"um",""),"mm","")) | AK9: =TRIM(SUBSTITUTE(SUBSTITUTE(SUBSTITUTE(SUBSTITUTE(SUBSTITUTE(SUBSTITUTE(SUBSTITUTE(SUBSTITUTE(SUBSTITUTE(SUBSTITUTE(SUBSTITUTE(SUBSTITUTE(SUBSTITUTE(LOWER(SUBSTITUTE(SUBSTITUTE(SUBSTITUTE(SUBSTITUTE(SUBSTITUTE(J9,"×","x"),"·",""),"−","-"),"–","-"),"^","")),"μ","u"),"µ","u")," ",""),"k1=",""),"k2=",""),"k3=",""),"kd=",""),"ka=",""),"k=",""),"°c",""),"m-1",""),"um",""),"mm","")) | AL9: =TRIM(SUBSTITUTE(SUBSTITUTE(SUBSTITUTE(SUBSTITUTE(SUBSTITUTE(SUBSTITUTE(SUBSTITUTE(SUBSTITUTE(SUBSTITUTE(SUBSTITUTE(SUBSTITUTE(SUBSTITUTE(SUBSTITUTE(LOWER(SUBSTITUTE(SUBSTITUTE(SUBSTITUTE(SUBSTITUTE(SUBSTITUTE(K9,"×","x"),"·",""),"−","-"),"–","-"),"^","")),"μ","u"),"µ","u")," ",""),"k1=",""),"k2=",""),"k3=",""),"kd=",""),"ka=",""),"k=",""),"°c",""),"m-1",""),"um",""),"mm","")) | AM9: =TRIM(SUBSTITUTE(SUBSTITUTE(SUBSTITUTE(SUBSTITUTE(SUBSTITUTE(SUBSTITUTE(SUBSTITUTE(SUBSTITUTE(SUBSTITUTE(SUBSTITUTE(SUBSTITUTE(SUBSTITUTE(SUBSTITUTE(LOWER(SUBSTITUTE(SUBSTITUTE(SUBSTITUTE(SUBSTITUTE(SUBSTITUTE(L9,"×","x"),"·",""),"−","-"),"–","-"),"^","")),"μ","u"),"µ","u")," ",""),"k1=",""),"k2=",""),"k3=",""),"kd=",""),"ka=",""),"k=",""),"°c",""),"m-1",""),"um",""),"mm","")) | AN9: =TRIM(SUBSTITUTE(SUBSTITUTE(SUBSTITUTE(SUBSTITUTE(SUBSTITUTE(SUBSTITUTE(SUBSTITUTE(SUBSTITUTE(SUBSTITUTE(SUBSTITUTE(SUBSTITUTE(SUBSTITUTE(SUBSTITUTE(LOWER(SUBSTITUTE(SUBSTITUTE(SUBSTITUTE(SUBSTITUTE(SUBSTITUTE(M9,"×","x"),"·",""),"−","-"),"–","-"),"^","")),"μ","u"),"µ","u")," ",""),"k1=",""),"k2=",""),"k3=",""),"kd=",""),"ka=",""),"k=",""),"°c",""),"m-1",""),"um",""),"mm","")) | AO9: =TRIM(SUBSTITUTE(SUBSTITUTE(SUBSTITUTE(SUBSTITUTE(SUBSTITUTE(SUBSTITUTE(SUBSTITUTE(SUBSTITUTE(SUBSTITUTE(SUBSTITUTE(SUBSTITUTE(SUBSTITUTE(SUBSTITUTE(LOWER(SUBSTITUTE(SUBSTITUTE(SUBSTITUTE(SUBSTITUTE(SUBSTITUTE(N9,"×","x"),"·",""),"−","-"),"–","-"),"^","")),"μ","u"),"µ","u")," ",""),"k1=",""),"k2=",""),"k3=",""),"kd=",""),"ka=",""),"k=",""),"°c",""),"m-1",""),"um",""),"mm","")) | AP9: =TRIM(SUBSTITUTE(SUBSTITUTE(SUBSTITUTE(SUBSTITUTE(SUBSTITUTE(SUBSTITUTE(SUBSTITUTE(SUBSTITUTE(SUBSTITUTE(SUBSTITUTE(SUBSTITUTE(SUBSTITUTE(SUBSTITUTE(LOWER(SUBSTITUTE(SUBSTITUTE(SUBSTITUTE(SUBSTITUTE(SUBSTITUTE(O9,"×","x"),"·",""),"−","-"),"–","-"),"^","")),"μ","u"),"µ","u")," ",""),"k1=",""),"k2=",""),"k3=",""),"kd=",""),"ka=",""),"k=",""),"°c",""),"m-1",""),"um",""),"mm","")) | AQ9: =TRIM(SUBSTITUTE(SUBSTITUTE(SUBSTITUTE(SUBSTITUTE(SUBSTITUTE(SUBSTITUTE(SUBSTITUTE(SUBSTITUTE(SUBSTITUTE(SUBSTITUTE(SUBSTITUTE(SUBSTITUTE(SUBSTITUTE(LOWER(SUBSTITUTE(SUBSTITUTE(SUBSTITUTE(SUBSTITUTE(SUBSTITUTE(P9,"×","x"),"·",""),"−","-"),"–","-"),"^","")),"μ","u"),"µ","u")," ",""),"k1=",""),"k2=",""),"k3=",""),"kd=",""),"ka=",""),"k=",""),"°c",""),"m-1",""),"um",""),"mm",""))
W11: RUN TOTAL: | Y11: =SUM(AA4:AA9) | Z11: out of 42 | AA11: =IF(SUM(AA4:AA9)=0,"",Y11/42)
W12: Accuracy % →
B14: Extra rows your model produced beyond these 6 (optional, for feedback):

Sheet Run 2
A1: RUN 2 | C1: Paste your model's values into the BLUE columns, one benchmark row at a time. The GREEN columns check them automatically.
B2: BENCHMARK — do not edit | J2: YOUR MODEL — paste values here | R2: AUTO-CHECK (rough — you have the final say) | Y2: SCORE
A3: Row | B3: Species | C3: Temp (°C) | D3: Troponin complex | E3: Bound Ca2+ measure | F3: Mg (mM) | G3: Kd (M^-1) | H3: K (µM) | J3: Species | K3: Temp (°C) | L3: Troponin complex | M3: Bound Ca2+ measure | N3: Mg (mM) | O3: Kd (M^-1) | P3: K (µM) | R3: Species | S3: Temp (°C) | T3: Troponin complex | U3: Bound Ca2+ measure | V3: Mg (mM) | W3: Kd (M^-1) | X3: K (µM) | Y3: Auto /7 | Z3: Your /7 (edit only if you disagree) | AA3: Final /7 | AC3: norm(GT):Species | AD3: norm(GT):Temp (°C) | AE3: norm(GT):Troponin complex | AF3: norm(GT):Bound Ca2+ measure | AG3: norm(GT):Mg (mM) | AH3: norm(GT):Kd (M^-1) | AI3: norm(GT):K (µM) | AK3: norm(you):Species | AL3: norm(you):Temp (°C) | AM3: norm(you):Troponin complex | AN3: norm(you):Bound Ca2+ measure | AO3: norm(you):Mg (mM) | AP3: norm(you):Kd (M^-1) | AQ3: norm(you):K (µM)
A4: 1 | B4: Bovine | C4: 4 | D4: TnC | E4: SC | F4: None | G4: 2.5 x 10^5 | H4: 4 | R4: =IF(J4="",0,IF(EXACT($AC4,$AK4),1,IF(IFERROR(VALUE($AC4)=VALUE($AK4),FALSE),1,0))) | S4: =IF(K4="",0,IF(EXACT($AD4,$AL4),1,IF(IFERROR(VALUE($AD4)=VALUE($AL4),FALSE),1,0))) | T4: =IF(L4="",0,IF(EXACT($AE4,$AM4),1,IF(IFERROR(VALUE($AE4)=VALUE($AM4),FALSE),1,0))) | U4: =IF(M4="",0,IF(EXACT($AF4,$AN4),1,IF(IFERROR(VALUE($AF4)=VALUE($AN4),FALSE),1,0))) | V4: =IF(N4="",0,IF(EXACT($AG4,$AO4),1,IF(IFERROR(VALUE($AG4)=VALUE($AO4),FALSE),1,0))) | W4: =IF(O4="",0,IF(EXACT($AH4,$AP4),1,IF(IFERROR(VALUE($AH4)=VALUE($AP4),FALSE),1,0))) | X4: =IF(P4="",0,IF(EXACT($AI4,$AQ4),1,IF(IFERROR(VALUE($AI4)=VALUE($AQ4),FALSE),1,0))) | Y4: =SUM(R4:X4) | AA4: =IF(Z4="",Y4,Z4) | AC4: =TRIM(SUBSTITUTE(SUBSTITUTE(SUBSTITUTE(SUBSTITUTE(SUBSTITUTE(SUBSTITUTE(SUBSTITUTE(SUBSTITUTE(SUBSTITUTE(SUBSTITUTE(SUBSTITUTE(SUBSTITUTE(SUBSTITUTE(LOWER(SUBSTITUTE(SUBSTITUTE(SUBSTITUTE(SUBSTITUTE(SUBSTITUTE(B4,"×","x"),"·",""),"−","-"),"–","-"),"^","")),"μ","u"),"µ","u")," ",""),"k1=",""),"k2=",""),"k3=",""),"kd=",""),"ka=",""),"k=",""),"°c",""),"m-1",""),"um",""),"mm","")) | AD4: =TRIM(SUBSTITUTE(SUBSTITUTE(SUBSTITUTE(SUBSTITUTE(SUBSTITUTE(SUBSTITUTE(SUBSTITUTE(SUBSTITUTE(SUBSTITUTE(SUBSTITUTE(SUBSTITUTE(SUBSTITUTE(SUBSTITUTE(LOWER(SUBSTITUTE(SUBSTITUTE(SUBSTITUTE(SUBSTITUTE(SUBSTITUTE(C4,"×","x"),"·",""),"−","-"),"–","-"),"^","")),"μ","u"),"µ","u")," ",""),"k1=",""),"k2=",""),"k3=",""),"kd=",""),"ka=",""),"k=",""),"°c",""),"m-1",""),"um",""),"mm","")) | AE4: =TRIM(SUBSTITUTE(SUBSTITUTE(SUBSTITUTE(SUBSTITUTE(SUBSTITUTE(SUBSTITUTE(SUBSTITUTE(SUBSTITUTE(SUBSTITUTE(SUBSTITUTE(SUBSTITUTE(SUBSTITUTE(SUBSTITUTE(LOWER(SUBSTITUTE(SUBSTITUTE(SUBSTITUTE(SUBSTITUTE(SUBSTITUTE(D4,"×","x"),"·",""),"−","-"),"–","-"),"^","")),"μ","u"),"µ","u")," ",""),"k1=",""),"k2=",""),"k3=",""),"kd=",""),"ka=",""),"k=",""),"°c",""),"m-1",""),"um",""),"mm","")) | AF4: =TRIM(SUBSTITUTE(SUBSTITUTE(SUBSTITUTE(SUBSTITUTE(SUBSTITUTE(SUBSTITUTE(SUBSTITUTE(SUBSTITUTE(SUBSTITUTE(SUBSTITUTE(SUBSTITUTE(SUBSTITUTE(SUBSTITUTE(LOWER(SUBSTITUTE(SUBSTITUTE(SUBSTITUTE(SUBSTITUTE(SUBSTITUTE(E4,"×","x"),"·",""),"−","-"),"–","-"),"^","")),"μ","u"),"µ","u")," ",""),"k1=",""),"k2=",""),"k3=",""),"kd=",""),"ka=",""),"k=",""),"°c",""),"m-1",""),"um",""),"mm","")) | AG4: =TRIM(SUBSTITUTE(SUBSTITUTE(SUBSTITUTE(SUBSTITUTE(SUBSTITUTE(SUBSTITUTE(SUBSTITUTE(SUBSTITUTE(SUBSTITUTE(SUBSTITUTE(SUBSTITUTE(SUBSTITUTE(SUBSTITUTE(LOWER(SUBSTITUTE(SUBSTITUTE(SUBSTITUTE(SUBSTITUTE(SUBSTITUTE(F4,"×","x"),"·",""),"−","-"),"–","-"),"^","")),"μ","u"),"µ","u")," ",""),"k1=",""),"k2=",""),"k3=",""),"kd=",""),"ka=",""),"k=",""),"°c",""),"m-1",""),"um",""),"mm","")) | AH4: =TRIM(SUBSTITUTE(SUBSTITUTE(SUBSTITUTE(SUBSTITUTE(SUBSTITUTE(SUBSTITUTE(SUBSTITUTE(SUBSTITUTE(SUBSTITUTE(SUBSTITUTE(SUBSTITUTE(SUBSTITUTE(SUBSTITUTE(LOWER(SUBSTITUTE(SUBSTITUTE(SUBSTITUTE(SUBSTITUTE(SUBSTITUTE(G4,"×","x"),"·",""),"−","-"),"–","-"),"^","")),"μ","u"),"µ","u")," ",""),"k1=",""),"k2=",""),"k3=",""),"kd=",""),"ka=",""),"k=",""),"°c",""),"m-1",""),"um",""),"mm","")) | AI4: =TRIM(SUBSTITUTE(SUBSTITUTE(SUBSTITUTE(SUBSTITUTE(SUBSTITUTE(SUBSTITUTE(SUBSTITUTE(SUBSTITUTE(SUBSTITUTE(SUBSTITUTE(SUBSTITUTE(SUBSTITUTE(SUBSTITUTE(LOWER(SUBSTITUTE(SUBSTITUTE(SUBSTITUTE(SUBSTITUTE(SUBSTITUTE(H4,"×","x"),"·",""),"−","-"),"–","-"),"^","")),"μ","u"),"µ","u")," ",""),"k1=",""),"k2=",""),"k3=",""),"kd=",""),"ka=",""),"k=",""),"°c",""),"m-1",""),"um",""),"mm","")) | AK4: =TRIM(SUBSTITUTE(SUBSTITUTE(SUBSTITUTE(SUBSTITUTE(SUBSTITUTE(SUBSTITUTE(SUBSTITUTE(SUBSTITUTE(SUBSTITUTE(SUBSTITUTE(SUBSTITUTE(SUBSTITUTE(SUBSTITUTE(LOWER(SUBSTITUTE(SUBSTITUTE(SUBSTITUTE(SUBSTITUTE(SUBSTITUTE(J4,"×","x"),"·",""),"−","-"),"–","-"),"^","")),"μ","u"),"µ","u")," ",""),"k1=",""),"k2=",""),"k3=",""),"kd=",""),"ka=",""),"k=",""),"°c",""),"m-1",""),"um",""),"mm","")) | AL4: =TRIM(SUBSTITUTE(SUBSTITUTE(SUBSTITUTE(SUBSTITUTE(SUBSTITUTE(SUBSTITUTE(SUBSTITUTE(SUBSTITUTE(SUBSTITUTE(SUBSTITUTE(SUBSTITUTE(SUBSTITUTE(SUBSTITUTE(LOWER(SUBSTITUTE(SUBSTITUTE(SUBSTITUTE(SUBSTITUTE(SUBSTITUTE(K4,"×","x"),"·",""),"−","-"),"–","-"),"^","")),"μ","u"),"µ","u")," ",""),"k1=",""),"k2=",""),"k3=",""),"kd=",""),"ka=",""),"k=",""),"°c",""),"m-1",""),"um",""),"mm","")) | AM4: =TRIM(SUBSTITUTE(SUBSTITUTE(SUBSTITUTE(SUBSTITUTE(SUBSTITUTE(SUBSTITUTE(SUBSTITUTE(SUBSTITUTE(SUBSTITUTE(SUBSTITUTE(SUBSTITUTE(SUBSTITUTE(SUBSTITUTE(LOWER(SUBSTITUTE(SUBSTITUTE(SUBSTITUTE(SUBSTITUTE(SUBSTITUTE(L4,"×","x"),"·",""),"−","-"),"–","-"),"^","")),"μ","u"),"µ","u")," ",""),"k1=",""),"k2=",""),"k3=",""),"kd=",""),"ka=",""),"k=",""),"°c",""),"m-1",""),"um",""),"mm","")) | AN4: =TRIM(SUBSTITUTE(SUBSTITUTE(SUBSTITUTE(SUBSTITUTE(SUBSTITUTE(SUBSTITUTE(SUBSTITUTE(SUBSTITUTE(SUBSTITUTE(SUBSTITUTE(SUBSTITUTE(SUBSTITUTE(SUBSTITUTE(LOWER(SUBSTITUTE(SUBSTITUTE(SUBSTITUTE(SUBSTITUTE(SUBSTITUTE(M4,"×","x"),"·",""),"−","-"),"–","-"),"^","")),"μ","u"),"µ","u")," ",""),"k1=",""),"k2=",""),"k3=",""),"kd=",""),"ka=",""),"k=",""),"°c",""),"m-1",""),"um",""),"mm","")) | AO4: =TRIM(SUBSTITUTE(SUBSTITUTE(SUBSTITUTE(SUBSTITUTE(SUBSTITUTE(SUBSTITUTE(SUBSTITUTE(SUBSTITUTE(SUBSTITUTE(SUBSTITUTE(SUBSTITUTE(SUBSTITUTE(SUBSTITUTE(LOWER(SUBSTITUTE(SUBSTITUTE(SUBSTITUTE(SUBSTITUTE(SUBSTITUTE(N4,"×","x"),"·",""),"−","-"),"–","-"),"^","")),"μ","u"),"µ","u")," ",""),"k1=",""),"k2=",""),"k3=",""),"kd=",""),"ka=",""),"k=",""),"°c",""),"m-1",""),"um",""),"mm","")) | AP4: =TRIM(SUBSTITUTE(SUBSTITUTE(SUBSTITUTE(SUBSTITUTE(SUBSTITUTE(SUBSTITUTE(SUBSTITUTE(SUBSTITUTE(SUBSTITUTE(SUBSTITUTE(SUBSTITUTE(SUBSTITUTE(SUBSTITUTE(LOWER(SUBSTITUTE(SUBSTITUTE(SUBSTITUTE(SUBSTITUTE(SUBSTITUTE(O4,"×","x"),"·",""),"−","-"),"–","-"),"^","")),"μ","u"),"µ","u")," ",""),"k1=",""),"k2=",""),"k3=",""),"kd=",""),"ka=",""),"k=",""),"°c",""),"m-1",""),"um",""),"mm","")) | AQ4: =TRIM(SUBSTITUTE(SUBSTITUTE(SUBSTITUTE(SUBSTITUTE(SUBSTITUTE(SUBSTITUTE(SUBSTITUTE(SUBSTITUTE(SUBSTITUTE(SUBSTITUTE(SUBSTITUTE(SUBSTITUTE(SUBSTITUTE(LOWER(SUBSTITUTE(SUBSTITUTE(SUBSTITUTE(SUBSTITUTE(SUBSTITUTE(P4,"×","x"),"·",""),"−","-"),"–","-"),"^","")),"μ","u"),"µ","u")," ",""),"k1=",""),"k2=",""),"k3=",""),"kd=",""),"ka=",""),"k=",""),"°c",""),"m-1",""),"um",""),"mm",""))
A5: 2 | B5: Bovine | C5: 4 | D5: TnC | E5: SC | F5: 4 | G5: 2.5 x 10^5 | H5: 4 | R5: =IF(J5="",0,IF(EXACT($AC5,$AK5),1,IF(IFERROR(VALUE($AC5)=VALUE($AK5),FALSE),1,0))) | S5: =IF(K5="",0,IF(EXACT($AD5,$AL5),1,IF(IFERROR(VALUE($AD5)=VALUE($AL5),FALSE),1,0))) | T5: =IF(L5="",0,IF(EXACT($AE5,$AM5),1,IF(IFERROR(VALUE($AE5)=VALUE($AM5),FALSE),1,0))) | U5: =IF(M5="",0,IF(EXACT($AF5,$AN5),1,IF(IFERROR(VALUE($AF5)=VALUE($AN5),FALSE),1,0))) | V5: =IF(N5="",0,IF(EXACT($AG5,$AO5),1,IF(IFERROR(VALUE($AG5)=VALUE($AO5),FALSE),1,0))) | W5: =IF(O5="",0,IF(EXACT($AH5,$AP5),1,IF(IFERROR(VALUE($AH5)=VALUE($AP5),FALSE),1,0))) | X5: =IF(P5="",0,IF(EXACT($AI5,$AQ5),1,IF(IFERROR(VALUE($AI5)=VALUE($AQ5),FALSE),1,0))) | Y5: =SUM(R5:X5) | AA5: =IF(Z5="",Y5,Z5) | AC5: =TRIM(SUBSTITUTE(SUBSTITUTE(SUBSTITUTE(SUBSTITUTE(SUBSTITUTE(SUBSTITUTE(SUBSTITUTE(SUBSTITUTE(SUBSTITUTE(SUBSTITUTE(SUBSTITUTE(SUBSTITUTE(SUBSTITUTE(LOWER(SUBSTITUTE(SUBSTITUTE(SUBSTITUTE(SUBSTITUTE(SUBSTITUTE(B5,"×","x"),"·",""),"−","-"),"–","-"),"^","")),"μ","u"),"µ","u")," ",""),"k1=",""),"k2=",""),"k3=",""),"kd=",""),"ka=",""),"k=",""),"°c",""),"m-1",""),"um",""),"mm","")) | AD5: =TRIM(SUBSTITUTE(SUBSTITUTE(SUBSTITUTE(SUBSTITUTE(SUBSTITUTE(SUBSTITUTE(SUBSTITUTE(SUBSTITUTE(SUBSTITUTE(SUBSTITUTE(SUBSTITUTE(SUBSTITUTE(SUBSTITUTE(LOWER(SUBSTITUTE(SUBSTITUTE(SUBSTITUTE(SUBSTITUTE(SUBSTITUTE(C5,"×","x"),"·",""),"−","-"),"–","-"),"^","")),"μ","u"),"µ","u")," ",""),"k1=",""),"k2=",""),"k3=",""),"kd=",""),"ka=",""),"k=",""),"°c",""),"m-1",""),"um",""),"mm","")) | AE5: =TRIM(SUBSTITUTE(SUBSTITUTE(SUBSTITUTE(SUBSTITUTE(SUBSTITUTE(SUBSTITUTE(SUBSTITUTE(SUBSTITUTE(SUBSTITUTE(SUBSTITUTE(SUBSTITUTE(SUBSTITUTE(SUBSTITUTE(LOWER(SUBSTITUTE(SUBSTITUTE(SUBSTITUTE(SUBSTITUTE(SUBSTITUTE(D5,"×","x"),"·",""),"−","-"),"–","-"),"^","")),"μ","u"),"µ","u")," ",""),"k1=",""),"k2=",""),"k3=",""),"kd=",""),"ka=",""),"k=",""),"°c",""),"m-1",""),"um",""),"mm","")) | AF5: =TRIM(SUBSTITUTE(SUBSTITUTE(SUBSTITUTE(SUBSTITUTE(SUBSTITUTE(SUBSTITUTE(SUBSTITUTE(SUBSTITUTE(SUBSTITUTE(SUBSTITUTE(SUBSTITUTE(SUBSTITUTE(SUBSTITUTE(LOWER(SUBSTITUTE(SUBSTITUTE(SUBSTITUTE(SUBSTITUTE(SUBSTITUTE(E5,"×","x"),"·",""),"−","-"),"–","-"),"^","")),"μ","u"),"µ","u")," ",""),"k1=",""),"k2=",""),"k3=",""),"kd=",""),"ka=",""),"k=",""),"°c",""),"m-1",""),"um",""),"mm","")) | AG5: =TRIM(SUBSTITUTE(SUBSTITUTE(SUBSTITUTE(SUBSTITUTE(SUBSTITUTE(SUBSTITUTE(SUBSTITUTE(SUBSTITUTE(SUBSTITUTE(SUBSTITUTE(SUBSTITUTE(SUBSTITUTE(SUBSTITUTE(LOWER(SUBSTITUTE(SUBSTITUTE(SUBSTITUTE(SUBSTITUTE(SUBSTITUTE(F5,"×","x"),"·",""),"−","-"),"–","-"),"^","")),"μ","u"),"µ","u")," ",""),"k1=",""),"k2=",""),"k3=",""),"kd=",""),"ka=",""),"k=",""),"°c",""),"m-1",""),"um",""),"mm","")) | AH5: =TRIM(SUBSTITUTE(SUBSTITUTE(SUBSTITUTE(SUBSTITUTE(SUBSTITUTE(SUBSTITUTE(SUBSTITUTE(SUBSTITUTE(SUBSTITUTE(SUBSTITUTE(SUBSTITUTE(SUBSTITUTE(SUBSTITUTE(LOWER(SUBSTITUTE(SUBSTITUTE(SUBSTITUTE(SUBSTITUTE(SUBSTITUTE(G5,"×","x"),"·",""),"−","-"),"–","-"),"^","")),"μ","u"),"µ","u")," ",""),"k1=",""),"k2=",""),"k3=",""),"kd=",""),"ka=",""),"k=",""),"°c",""),"m-1",""),"um",""),"mm","")) | AI5: =TRIM(SUBSTITUTE(SUBSTITUTE(SUBSTITUTE(SUBSTITUTE(SUBSTITUTE(SUBSTITUTE(SUBSTITUTE(SUBSTITUTE(SUBSTITUTE(SUBSTITUTE(SUBSTITUTE(SUBSTITUTE(SUBSTITUTE(LOWER(SUBSTITUTE(SUBSTITUTE(SUBSTITUTE(SUBSTITUTE(SUBSTITUTE(H5,"×","x"),"·",""),"−","-"),"–","-"),"^","")),"μ","u"),"µ","u")," ",""),"k1=",""),"k2=",""),"k3=",""),"kd=",""),"ka=",""),"k=",""),"°c",""),"m-1",""),"um",""),"mm","")) | AK5: =TRIM(SUBSTITUTE(SUBSTITUTE(SUBSTITUTE(SUBSTITUTE(SUBSTITUTE(SUBSTITUTE(SUBSTITUTE(SUBSTITUTE(SUBSTITUTE(SUBSTITUTE(SUBSTITUTE(SUBSTITUTE(SUBSTITUTE(LOWER(SUBSTITUTE(SUBSTITUTE(SUBSTITUTE(SUBSTITUTE(SUBSTITUTE(J5,"×","x"),"·",""),"−","-"),"–","-"),"^","")),"μ","u"),"µ","u")," ",""),"k1=",""),"k2=",""),"k3=",""),"kd=",""),"ka=",""),"k=",""),"°c",""),"m-1",""),"um",""),"mm","")) | AL5: =TRIM(SUBSTITUTE(SUBSTITUTE(SUBSTITUTE(SUBSTITUTE(SUBSTITUTE(SUBSTITUTE(SUBSTITUTE(SUBSTITUTE(SUBSTITUTE(SUBSTITUTE(SUBSTITUTE(SUBSTITUTE(SUBSTITUTE(LOWER(SUBSTITUTE(SUBSTITUTE(SUBSTITUTE(SUBSTITUTE(SUBSTITUTE(K5,"×","x"),"·",""),"−","-"),"–","-"),"^","")),"μ","u"),"µ","u")," ",""),"k1=",""),"k2=",""),"k3=",""),"kd=",""),"ka=",""),"k=",""),"°c",""),"m-1",""),"um",""),"mm","")) | AM5: =TRIM(SUBSTITUTE(SUBSTITUTE(SUBSTITUTE(SUBSTITUTE(SUBSTITUTE(SUBSTITUTE(SUBSTITUTE(SUBSTITUTE(SUBSTITUTE(SUBSTITUTE(SUBSTITUTE(SUBSTITUTE(SUBSTITUTE(LOWER(SUBSTITUTE(SUBSTITUTE(SUBSTITUTE(SUBSTITUTE(SUBSTITUTE(L5,"×","x"),"·",""),"−","-"),"–","-"),"^","")),"μ","u"),"µ","u")," ",""),"k1=",""),"k2=",""),"k3=",""),"kd=",""),"ka=",""),"k=",""),"°c",""),"m-1",""),"um",""),"mm","")) | AN5: =TRIM(SUBSTITUTE(SUBSTITUTE(SUBSTITUTE(SUBSTITUTE(SUBSTITUTE(SUBSTITUTE(SUBSTITUTE(SUBSTITUTE(SUBSTITUTE(SUBSTITUTE(SUBSTITUTE(SUBSTITUTE(SUBSTITUTE(LOWER(SUBSTITUTE(SUBSTITUTE(SUBSTITUTE(SUBSTITUTE(SUBSTITUTE(M5,"×","x"),"·",""),"−","-"),"–","-"),"^","")),"μ","u"),"µ","u")," ",""),"k1=",""),"k2=",""),"k3=",""),"kd=",""),"ka=",""),"k=",""),"°c",""),"m-1",""),"um",""),"mm","")) | AO5: =TRIM(SUBSTITUTE(SUBSTITUTE(SUBSTITUTE(SUBSTITUTE(SUBSTITUTE(SUBSTITUTE(SUBSTITUTE(SUBSTITUTE(SUBSTITUTE(SUBSTITUTE(SUBSTITUTE(SUBSTITUTE(SUBSTITUTE(LOWER(SUBSTITUTE(SUBSTITUTE(SUBSTITUTE(SUBSTITUTE(SUBSTITUTE(N5,"×","x"),"·",""),"−","-"),"–","-"),"^","")),"μ","u"),"µ","u")," ",""),"k1=",""),"k2=",""),"k3=",""),"kd=",""),"ka=",""),"k=",""),"°c",""),"m-1",""),"um",""),"mm","")) | AP5: =TRIM(SUBSTITUTE(SUBSTITUTE(SUBSTITUTE(SUBSTITUTE(SUBSTITUTE(SUBSTITUTE(SUBSTITUTE(SUBSTITUTE(SUBSTITUTE(SUBSTITUTE(SUBSTITUTE(SUBSTITUTE(SUBSTITUTE(LOWER(SUBSTITUTE(SUBSTITUTE(SUBSTITUTE(SUBSTITUTE(SUBSTITUTE(O5,"×","x"),"·",""),"−","-"),"–","-"),"^","")),"μ","u"),"µ","u")," ",""),"k1=",""),"k2=",""),"k3=",""),"kd=",""),"ka=",""),"k=",""),"°c",""),"m-1",""),"um",""),"mm","")) | AQ5: =TRIM(SUBSTITUTE(SUBSTITUTE(SUBSTITUTE(SUBSTITUTE(SUBSTITUTE(SUBSTITUTE(SUBSTITUTE(SUBSTITUTE(SUBSTITUTE(SUBSTITUTE(SUBSTITUTE(SUBSTITUTE(SUBSTITUTE(LOWER(SUBSTITUTE(SUBSTITUTE(SUBSTITUTE(SUBSTITUTE(SUBSTITUTE(P5,"×","x"),"·",""),"−","-"),"–","-"),"^","")),"μ","u"),"µ","u")," ",""),"k1=",""),"k2=",""),"k3=",""),"kd=",""),"ka=",""),"k=",""),"°c",""),"m-1",""),"um",""),"mm",""))
A6: 3 | B6: Bovine | C6: 4 | D6: TnC-TnI | E6: SC | F6: 4 | G6: 1 x 10^6 | H6: 1 | R6: =IF(J6="",0,IF(EXACT($AC6,$AK6),1,IF(IFERROR(VALUE($AC6)=VALUE($AK6),FALSE),1,0))) | S6: =IF(K6="",0,IF(EXACT($AD6,$AL6),1,IF(IFERROR(VALUE($AD6)=VALUE($AL6),FALSE),1,0))) | T6: =IF(L6="",0,IF(EXACT($AE6,$AM6),1,IF(IFERROR(VALUE($AE6)=VALUE($AM6),FALSE),1,0))) | U6: =IF(M6="",0,IF(EXACT($AF6,$AN6),1,IF(IFERROR(VALUE($AF6)=VALUE($AN6),FALSE),1,0))) | V6: =IF(N6="",0,IF(EXACT($AG6,$AO6),1,IF(IFERROR(VALUE($AG6)=VALUE($AO6),FALSE),1,0))) | W6: =IF(O6="",0,IF(EXACT($AH6,$AP6),1,IF(IFERROR(VALUE($AH6)=VALUE($AP6),FALSE),1,0))) | X6: =IF(P6="",0,IF(EXACT($AI6,$AQ6),1,IF(IFERROR(VALUE($AI6)=VALUE($AQ6),FALSE),1,0))) | Y6: =SUM(R6:X6) | AA6: =IF(Z6="",Y6,Z6) | AC6: =TRIM(SUBSTITUTE(SUBSTITUTE(SUBSTITUTE(SUBSTITUTE(SUBSTITUTE(SUBSTITUTE(SUBSTITUTE(SUBSTITUTE(SUBSTITUTE(SUBSTITUTE(SUBSTITUTE(SUBSTITUTE(SUBSTITUTE(LOWER(SUBSTITUTE(SUBSTITUTE(SUBSTITUTE(SUBSTITUTE(SUBSTITUTE(B6,"×","x"),"·",""),"−","-"),"–","-"),"^","")),"μ","u"),"µ","u")," ",""),"k1=",""),"k2=",""),"k3=",""),"kd=",""),"ka=",""),"k=",""),"°c",""),"m-1",""),"um",""),"mm","")) | AD6: =TRIM(SUBSTITUTE(SUBSTITUTE(SUBSTITUTE(SUBSTITUTE(SUBSTITUTE(SUBSTITUTE(SUBSTITUTE(SUBSTITUTE(SUBSTITUTE(SUBSTITUTE(SUBSTITUTE(SUBSTITUTE(SUBSTITUTE(LOWER(SUBSTITUTE(SUBSTITUTE(SUBSTITUTE(SUBSTITUTE(SUBSTITUTE(C6,"×","x"),"·",""),"−","-"),"–","-"),"^","")),"μ","u"),"µ","u")," ",""),"k1=",""),"k2=",""),"k3=",""),"kd=",""),"ka=",""),"k=",""),"°c",""),"m-1",""),"um",""),"mm","")) | AE6: =TRIM(SUBSTITUTE(SUBSTITUTE(SUBSTITUTE(SUBSTITUTE(SUBSTITUTE(SUBSTITUTE(SUBSTITUTE(SUBSTITUTE(SUBSTITUTE(SUBSTITUTE(SUBSTITUTE(SUBSTITUTE(SUBSTITUTE(LOWER(SUBSTITUTE(SUBSTITUTE(SUBSTITUTE(SUBSTITUTE(SUBSTITUTE(D6,"×","x"),"·",""),"−","-"),"–","-"),"^","")),"μ","u"),"µ","u")," ",""),"k1=",""),"k2=",""),"k3=",""),"kd=",""),"ka=",""),"k=",""),"°c",""),"m-1",""),"um",""),"mm","")) | AF6: =TRIM(SUBSTITUTE(SUBSTITUTE(SUBSTITUTE(SUBSTITUTE(SUBSTITUTE(SUBSTITUTE(SUBSTITUTE(SUBSTITUTE(SUBSTITUTE(SUBSTITUTE(SUBSTITUTE(SUBSTITUTE(SUBSTITUTE(LOWER(SUBSTITUTE(SUBSTITUTE(SUBSTITUTE(SUBSTITUTE(SUBSTITUTE(E6,"×","x"),"·",""),"−","-"),"–","-"),"^","")),"μ","u"),"µ","u")," ",""),"k1=",""),"k2=",""),"k3=",""),"kd=",""),"ka=",""),"k=",""),"°c",""),"m-1",""),"um",""),"mm","")) | AG6: =TRIM(SUBSTITUTE(SUBSTITUTE(SUBSTITUTE(SUBSTITUTE(SUBSTITUTE(SUBSTITUTE(SUBSTITUTE(SUBSTITUTE(SUBSTITUTE(SUBSTITUTE(SUBSTITUTE(SUBSTITUTE(SUBSTITUTE(LOWER(SUBSTITUTE(SUBSTITUTE(SUBSTITUTE(SUBSTITUTE(SUBSTITUTE(F6,"×","x"),"·",""),"−","-"),"–","-"),"^","")),"μ","u"),"µ","u")," ",""),"k1=",""),"k2=",""),"k3=",""),"kd=",""),"ka=",""),"k=",""),"°c",""),"m-1",""),"um",""),"mm","")) | AH6: =TRIM(SUBSTITUTE(SUBSTITUTE(SUBSTITUTE(SUBSTITUTE(SUBSTITUTE(SUBSTITUTE(SUBSTITUTE(SUBSTITUTE(SUBSTITUTE(SUBSTITUTE(SUBSTITUTE(SUBSTITUTE(SUBSTITUTE(LOWER(SUBSTITUTE(SUBSTITUTE(SUBSTITUTE(SUBSTITUTE(SUBSTITUTE(G6,"×","x"),"·",""),"−","-"),"–","-"),"^","")),"μ","u"),"µ","u")," ",""),"k1=",""),"k2=",""),"k3=",""),"kd=",""),"ka=",""),"k=",""),"°c",""),"m-1",""),"um",""),"mm","")) | AI6: =TRIM(SUBSTITUTE(SUBSTITUTE(SUBSTITUTE(SUBSTITUTE(SUBSTITUTE(SUBSTITUTE(SUBSTITUTE(SUBSTITUTE(SUBSTITUTE(SUBSTITUTE(SUBSTITUTE(SUBSTITUTE(SUBSTITUTE(LOWER(SUBSTITUTE(SUBSTITUTE(SUBSTITUTE(SUBSTITUTE(SUBSTITUTE(H6,"×","x"),"·",""),"−","-"),"–","-"),"^","")),"μ","u"),"µ","u")," ",""),"k1=",""),"k2=",""),"k3=",""),"kd=",""),"ka=",""),"k=",""),"°c",""),"m-1",""),"um",""),"mm","")) | AK6: =TRIM(SUBSTITUTE(SUBSTITUTE(SUBSTITUTE(SUBSTITUTE(SUBSTITUTE(SUBSTITUTE(SUBSTITUTE(SUBSTITUTE(SUBSTITUTE(SUBSTITUTE(SUBSTITUTE(SUBSTITUTE(SUBSTITUTE(LOWER(SUBSTITUTE(SUBSTITUTE(SUBSTITUTE(SUBSTITUTE(SUBSTITUTE(J6,"×","x"),"·",""),"−","-"),"–","-"),"^","")),"μ","u"),"µ","u")," ",""),"k1=",""),"k2=",""),"k3=",""),"kd=",""),"ka=",""),"k=",""),"°c",""),"m-1",""),"um",""),"mm","")) | AL6: =TRIM(SUBSTITUTE(SUBSTITUTE(SUBSTITUTE(SUBSTITUTE(SUBSTITUTE(SUBSTITUTE(SUBSTITUTE(SUBSTITUTE(SUBSTITUTE(SUBSTITUTE(SUBSTITUTE(SUBSTITUTE(SUBSTITUTE(LOWER(SUBSTITUTE(SUBSTITUTE(SUBSTITUTE(SUBSTITUTE(SUBSTITUTE(K6,"×","x"),"·",""),"−","-"),"–","-"),"^","")),"μ","u"),"µ","u")," ",""),"k1=",""),"k2=",""),"k3=",""),"kd=",""),"ka=",""),"k=",""),"°c",""),"m-1",""),"um",""),"mm","")) | AM6: =TRIM(SUBSTITUTE(SUBSTITUTE(SUBSTITUTE(SUBSTITUTE(SUBSTITUTE(SUBSTITUTE(SUBSTITUTE(SUBSTITUTE(SUBSTITUTE(SUBSTITUTE(SUBSTITUTE(SUBSTITUTE(SUBSTITUTE(LOWER(SUBSTITUTE(SUBSTITUTE(SUBSTITUTE(SUBSTITUTE(SUBSTITUTE(L6,"×","x"),"·",""),"−","-"),"–","-"),"^","")),"μ","u"),"µ","u")," ",""),"k1=",""),"k2=",""),"k3=",""),"kd=",""),"ka=",""),"k=",""),"°c",""),"m-1",""),"um",""),"mm","")) | AN6: =TRIM(SUBSTITUTE(SUBSTITUTE(SUBSTITUTE(SUBSTITUTE(SUBSTITUTE(SUBSTITUTE(SUBSTITUTE(SUBSTITUTE(SUBSTITUTE(SUBSTITUTE(SUBSTITUTE(SUBSTITUTE(SUBSTITUTE(LOWER(SUBSTITUTE(SUBSTITUTE(SUBSTITUTE(SUBSTITUTE(SUBSTITUTE(M6,"×","x"),"·",""),"−","-"),"–","-"),"^","")),"μ","u"),"µ","u")," ",""),"k1=",""),"k2=",""),"k3=",""),"kd=",""),"ka=",""),"k=",""),"°c",""),"m-1",""),"um",""),"mm","")) | AO6: =TRIM(SUBSTITUTE(SUBSTITUTE(SUBSTITUTE(SUBSTITUTE(SUBSTITUTE(SUBSTITUTE(SUBSTITUTE(SUBSTITUTE(SUBSTITUTE(SUBSTITUTE(SUBSTITUTE(SUBSTITUTE(SUBSTITUTE(LOWER(SUBSTITUTE(SUBSTITUTE(SUBSTITUTE(SUBSTITUTE(SUBSTITUTE(N6,"×","x"),"·",""),"−","-"),"–","-"),"^","")),"μ","u"),"µ","u")," ",""),"k1=",""),"k2=",""),"k3=",""),"kd=",""),"ka=",""),"k=",""),"°c",""),"m-1",""),"um",""),"mm","")) | AP6: =TRIM(SUBSTITUTE(SUBSTITUTE(SUBSTITUTE(SUBSTITUTE(SUBSTITUTE(SUBSTITUTE(SUBSTITUTE(SUBSTITUTE(SUBSTITUTE(SUBSTITUTE(SUBSTITUTE(SUBSTITUTE(SUBSTITUTE(LOWER(SUBSTITUTE(SUBSTITUTE(SUBSTITUTE(SUBSTITUTE(SUBSTITUTE(O6,"×","x"),"·",""),"−","-"),"–","-"),"^","")),"μ","u"),"µ","u")," ",""),"k1=",""),"k2=",""),"k3=",""),"kd=",""),"ka=",""),"k=",""),"°c",""),"m-1",""),"um",""),"mm","")) | AQ6: =TRIM(SUBSTITUTE(SUBSTITUTE(SUBSTITUTE(SUBSTITUTE(SUBSTITUTE(SUBSTITUTE(SUBSTITUTE(SUBSTITUTE(SUBSTITUTE(SUBSTITUTE(SUBSTITUTE(SUBSTITUTE(SUBSTITUTE(LOWER(SUBSTITUTE(SUBSTITUTE(SUBSTITUTE(SUBSTITUTE(SUBSTITUTE(P6,"×","x"),"·",""),"−","-"),"–","-"),"^","")),"μ","u"),"µ","u")," ",""),"k1=",""),"k2=",""),"k3=",""),"kd=",""),"ka=",""),"k=",""),"°c",""),"m-1",""),"um",""),"mm",""))
